Workbook

Sheet 整趟總覽
B1: 整趟費用總覽
B2: 所有金額以元計，精確至 0.1 元；有待處理項目時請先補齊再結算。
B3: 全部支出 | C3: =SUM('第 1 天'!D46,'第 1 天'!F46,'第 1 天'!H46,'第 1 天'!J46,'第 1 天'!L46,'第 1 天'!N46,'第 1 天'!P46,'第 2 天'!D46,'第 2 天'!F46,'第 2 天'!H46,'第 2 天'!J46,'第 2 天'!L46,'第 2 天'!N46,'第 2 天'!P46,'第 3 天'!D46,'第 3 天'!F46,'第 3 天'!H46,'第 3 天'!J46,'第 3 天'!L46,'第 3 天'!N46,'第 3 天'!P46,'第 4 天'!D46,'第 4 天'!F46,'第 4 天'!H46,'第 4 天'!J46,'第 4 天'!L46,'第 4 天'!N46,'第 4 天'!P46,'第 5 天'!D46,'第 5 天'!F46,'第 5 天'!H46,'第 5 天'!J46,'第 5 天'!L46,'第 5 天'!N46,'第 5 天'!P46,'第 6 天'!D46,'第 6 天'!F46,'第 6 天'!H46,'第 6 天'!J46,'第 6 天'!L46,'第 6 天'!N46,'第 6 天'!P46,'第 7 天'!D46,'第 7 天'!F46,'第 7 天'!H46,'第 7 天'!J46,'第 7 天'!L46,'第 7 天'!N46,'第 7 天'!P46,'第 8 天'!D46,'第 8 天'!F46,'第 8 天'!H46,'第 8 天'!J46,'第 8 天'!L46,'第 8 天'!N46,'第 8 天'!P46,'第 9 天'!D46,'第 9 天'!F46,'第 9 天'!H46,'第 9 天'!J46,'第 9 天'!L46,'第 9 天'!N46,'第 9 天'!P46,'第 10 天'!D46,'第 10 天'!F46,'第 10 天'!H46,'第 10 天'!J46,'第 10 天'!L46,'第 10 天'!N46,'第 10 天'!P46)/10 -> 0 | E3: 已分攤總額 | F3: =SUM('第 1 天'!D51,'第 1 天'!F51,'第 1 天'!H51,'第 1 天'!J51,'第 1 天'!L51,'第 1 天'!N51,'第 1 天'!P51,'第 2 天'!D51,'第 2 天'!F51,'第 2 天'!H51,'第 2 天'!J51,'第 2 天'!L51,'第 2 天'!N51,'第 2 天'!P51,'第 3 天'!D51,'第 3 天'!F51,'第 3 天'!H51,'第 3 天'!J51,'第 3 天'!L51,'第 3 天'!N51,'第 3 天'!P51,'第 4 天'!D51,'第 4 天'!F51,'第 4 天'!H51,'第 4 天'!J51,'第 4 天'!L51,'第 4 天'!N51,'第 4 天'!P51,'第 5 天'!D51,'第 5 天'!F51,'第 5 天'!H51,'第 5 天'!J51,'第 5 天'!L51,'第 5 天'!N51,'第 5 天'!P51,'第 6 天'!D51,'第 6 天'!F51,'第 6 天'!H51,'第 6 天'!J51,'第 6 天'!L51,'第 6 天'!N51,'第 6 天'!P51,'第 7 天'!D51,'第 7 天'!F51,'第 7 天'!H51,'第 7 天'!J51,'第 7 天'!L51,'第 7 天'!N51,'第 7 天'!P51,'第 8 天'!D51,'第 8 天'!F51,'第 8 天'!H51,'第 8 天'!J51,'第 8 天'!L51,'第 8 天'!N51,'第 8 天'!P51,'第 9 天'!D51,'第 9 天'!F51,'第 9 天'!H51,'第 9 天'!J51,'第 9 天'!L51,'第 9 天'!N51,'第 9 天'!P51,'第 10 天'!D51,'第 10 天'!F51,'第 10 天'!H51,'第 10 天'!J51,'第 10 天'!L51,'第 10 天'!N51,'第 10 天'!P51)/10 -> 0 | H3: 差額 | I3: =(SUM('第 1 天'!D46,'第 1 天'!F46,'第 1 天'!H46,'第 1 天'!J46,'第 1 天'!L46,'第 1 天'!N46,'第 1 天'!P46,'第 2 天'!D46,'第 2 天'!F46,'第 2 天'!H46,'第 2 天'!J46,'第 2 天'!L46,'第 2 天'!N46,'第 2 天'!P46,'第 3 天'!D46,'第 3 天'!F46,'第 3 天'!H46,'第 3 天'!J46,'第 3 天'!L46,'第 3 天'!N46,'第 3 天'!P46,'第 4 天'!D46,'第 4 天'!F46,'第 4 天'!H46,'第 4 天'!J46,'第 4 天'!L46,'第 4 天'!N46,'第 4 天'!P46,'第 5 天'!D46,'第 5 天'!F46,'第 5 天'!H46,'第 5 天'!J46,'第 5 天'!L46,'第 5 天'!N46,'第 5 天'!P46,'第 6 天'!D46,'第 6 天'!F46,'第 6 天'!H46,'第 6 天'!J46,'第 6 天'!L46,'第 6 天'!N46,'第 6 天'!P46,'第 7 天'!D46,'第 7 天'!F46,'第 7 天'!H46,'第 7 天'!J46,'第 7 天'!L46,'第 7 天'!N46,'第 7 天'!P46,'第 8 天'!D46,'第 8 天'!F46,'第 8 天'!H46,'第 8 天'!J46,'第 8 天'!L46,'第 8 天'!N46,'第 8 天'!P46,'第 9 天'!D46,'第 9 天'!F46,'第 9 天'!H46,'第 9 天'!J46,'第 9 天'!L46,'第 9 天'!N46,'第 9 天'!P46,'第 10 天'!D46,'第 10 天'!F46,'第 10 天'!H46,'第 10 天'!J46,'第 10 天'!L46,'第 10 天'!N46,'第 10 天'!P46)-SUM('第 1 天'!D51,'第 1 天'!F51,'第 1 天'!H51,'第 1 天'!J51,'第 1 天'!L51,'第 1 天'!N51,'第 1 天'!P51,'第 2 天'!D51,'第 2 天'!F51,'第 2 天'!H51,'第 2 天'!J51,'第 2 天'!L51,'第 2 天'!N51,'第 2 天'!P51,'第 3 天'!D51,'第 3 天'!F51,'第 3 天'!H51,'第 3 天'!J51,'第 3 天'!L51,'第 3 天'!N51,'第 3 天'!P51,'第 4 天'!D51,'第 4 天'!F51,'第 4 天'!H51,'第 4 天'!J51,'第 4 天'!L51,'第 4 天'!N51,'第 4 天'!P51,'第 5 天'!D51,'第 5 天'!F51,'第 5 天'!H51,'第 5 天'!J51,'第 5 天'!L51,'第 5 天'!N51,'第 5 天'!P51,'第 6 天'!D51,'第 6 天'!F51,'第 6 天'!H51,'第 6 天'!J51,'第 6 天'!L51,'第 6 天'!N51,'第 6 天'!P51,'第 7 天'!D51,'第 7 天'!F51,'第 7 天'!H51,'第 7 天'!J51,'第 7 天'!L51,'第 7 天'!N51,'第 7 天'!P51,'第 8 天'!D51,'第 8 天'!F51,'第 8 天'!H51,'第 8 天'!J51,'第 8 天'!L51,'第 8 天'!N51,'第 8 天'!P51,'第 9 天'!D51,'第 9 天'!F51,'第 9 天'!H51,'第 9 天'!J51,'第 9 天'!L51,'第 9 天'!N51,'第 9 天'!P51,'第 10 天'!D51,'第 10 天'!F51,'第 10 天'!H51,'第 10 天'!J51,'第 10 天'!L51,'第 10 天'!N51,'第 10 天'!P51))/10 -> 0
B4: 待處理費用（筆） | C4: =SUM(IF(LEN('第 1 天'!D10)>0,1,0),IF(LEN('第 1 天'!F10)>0,1,0),IF(LEN('第 1 天'!H10)>0,1,0),IF(LEN('第 1 天'!J10)>0,1,0),IF(LEN('第 1 天'!L10)>0,1,0),IF(LEN('第 1 天'!N10)>0,1,0),IF(LEN('第 1 天'!P10)>0,1,0),IF(LEN('第 2 天'!D10)>0,1,0),IF(LEN('第 2 天'!F10)>0,1,0),IF(LEN('第 2 天'!H10)>0,1,0),IF(LEN('第 2 天'!J10)>0,1,0),IF(LEN('第 2 天'!L10)>0,1,0),IF(LEN('第 2 天'!N10)>0,1,0),IF(LEN('第 2 天'!P10)>0,1,0),IF(LEN('第 3 天'!D10)>0,1,0),IF(LEN('第 3 天'!F10)>0,1,0),IF(LEN('第 3 天'!H10)>0,1,0),IF(LEN('第 3 天'!J10)>0,1,0),IF(LEN('第 3 天'!L10)>0,1,0),IF(LEN('第 3 天'!N10)>0,1,0),IF(LEN('第 3 天'!P10)>0,1,0),IF(LEN('第 4 天'!D10)>0,1,0),IF(LEN('第 4 天'!F10)>0,1,0),IF(LEN('第 4 天'!H10)>0,1,0),IF(LEN('第 4 天'!J10)>0,1,0),IF(LEN('第 4 天'!L10)>0,1,0),IF(LEN('第 4 天'!N10)>0,1,0),IF(LEN('第 4 天'!P10)>0,1,0),IF(LEN('第 5 天'!D10)>0,1,0),IF(LEN('第 5 天'!F10)>0,1,0),IF(LEN('第 5 天'!H10)>0,1,0),IF(LEN('第 5 天'!J10)>0,1,0),IF(LEN('第 5 天'!L10)>0,1,0),IF(LEN('第 5 天'!N10)>0,1,0),IF(LEN('第 5 天'!P10)>0,1,0),IF(LEN('第 6 天'!D10)>0,1,0),IF(LEN('第 6 天'!F10)>0,1,0),IF(LEN('第 6 天'!H10)>0,1,0),IF(LEN('第 6 天'!J10)>0,1,0),IF(LEN('第 6 天'!L10)>0,1,0),IF(LEN('第 6 天'!N10)>0,1,0),IF(LEN('第 6 天'!P10)>0,1,0),IF(LEN('第 7 天'!D10)>0,1,0),IF(LEN('第 7 天'!F10)>0,1,0),IF(LEN('第 7 天'!H10)>0,1,0),IF(LEN('第 7 天'!J10)>0,1,0),IF(LEN('第 7 天'!L10)>0,1,0),IF(LEN('第 7 天'!N10)>0,1,0),IF(LEN('第 7 天'!P10)>0,1,0),IF(LEN('第 8 天'!D10)>0,1,0),IF(LEN('第 8 天'!F10)>0,1,0),IF(LEN('第 8 天'!H10)>0,1,0),IF(LEN('第 8 天'!J10)>0,1,0),IF(LEN('第 8 天'!L10)>0,1,0),IF(LEN('第 8 天'!N10)>0,1,0),IF(LEN('第 8 天'!P10)>0,1,0),IF(LEN('第 9 天'!D10)>0,1,0),IF(LEN('第 9 天'!F10)>0,1,0),IF(LEN('第 9 天'!H10)>0,1,0),IF(LEN('第 9 天'!J10)>0,1,0),IF(LEN('第 9 天'!L10)>0,1,0),IF(LEN('第 9 天'!N10)>0,1,0),IF(LEN('第 9 天'!P10)>0,1,0),IF(LEN('第 10 天'!D10)>0,1,0),IF(LEN('第 10 天'!F10)>0,1,0),IF(LEN('第 10 天'!H10)>0,1,0),IF(LEN('第 10 天'!J10)>0,1,0),IF(LEN('第 10 天'!L10)>0,1,0),IF(LEN('第 10 天'!N10)>0,1,0),IF(LEN('第 10 天'!P10)>0,1,0)) -> 0 | E4: 未指定代墊 | F4: =(SUM('第 1 天'!D46,'第 1 天'!F46,'第 1 天'!H46,'第 1 天'!J46,'第 1 天'!L46,'第 1 天'!N46,'第 1 天'!P46,'第 2 天'!D46,'第 2 天'!F46,'第 2 天'!H46,'第 2 天'!J46,'第 2 天'!L46,'第 2 天'!N46,'第 2 天'!P46,'第 3 天'!D46,'第 3 天'!F46,'第 3 天'!H46,'第 3 天'!J46,'第 3 天'!L46,'第 3 天'!N46,'第 3 天'!P46,'第 4 天'!D46,'第 4 天'!F46,'第 4 天'!H46,'第 4 天'!J46,'第 4 天'!L46,'第 4 天'!N46,'第 4 天'!P46,'第 5 天'!D46,'第 5 天'!F46,'第 5 天'!H46,'第 5 天'!J46,'第 5 天'!L46,'第 5 天'!N46,'第 5 天'!P46,'第 6 天'!D46,'第 6 天'!F46,'第 6 天'!H46,'第 6 天'!J46,'第 6 天'!L46,'第 6 天'!N46,'第 6 天'!P46,'第 7 天'!D46,'第 7 天'!F46,'第 7 天'!H46,'第 7 天'!J46,'第 7 天'!L46,'第 7 天'!N46,'第 7 天'!P46,'第 8 天'!D46,'第 8 天'!F46,'第 8 天'!H46,'第 8 天'!J46,'第 8 天'!L46,'第 8 天'!N46,'第 8 天'!P46,'第 9 天'!D46,'第 9 天'!F46,'第 9 天'!H46,'第 9 天'!J46,'第 9 天'!L46,'第 9 天'!N46,'第 9 天'!P46,'第 10 天'!D46,'第 10 天'!F46,'第 10 天'!H46,'第 10 天'!J46,'第 10 天'!L46,'第 10 天'!N46,'第 10 天'!P46)-SUM(_計算!H2:H301))/10 -> 0
B5: 待處理費用的合法金額仍列支出與已代墊，但暫不分攤。請看下方核對清單。
A7: 固定 ID | B7: 姓名 | C7: 餐費合計 | D7: 油錢合計 | E7: 租車費合計 | F7: 其他費用合計 | G7: 總分攤 | H7: 已代墊 | I7: 還要付 | J7: 應收回
A8: P001 | B8: =IFERROR(INDEX(成員名單!$B$5:$B$34,MATCH($A8,成員名單!$A$5:$A$34,0))&"","") | C8: =SUMIF(_計算!$B$2:$B$301,$A8,_計算!$C$2:$C$301)/10 -> 0 | D8: =SUMIF(_計算!$B$2:$B$301,$A8,_計算!$D$2:$D$301)/10 -> 0 | E8: =SUMIF(_計算!$B$2:$B$301,$A8,_計算!$E$2:$E$301)/10 -> 0 | F8: =SUMIF(_計算!$B$2:$B$301,$A8,_計算!$F$2:$F$301)/10 -> 0 | G8: =SUMIF(_計算!$B$2:$B$301,$A8,_計算!$G$2:$G$301)/10 -> 0 | H8: =SUMIF(_計算!$B$2:$B$301,$A8,_計算!$H$2:$H$301)/10 -> 0 | I8: =MAX(0,(SUMIF(_計算!$B$2:$B$301,$A8,_計算!$G$2:$G$301)-SUMIF(_計算!$B$2:$B$301,$A8,_計算!$H$2:$H$301))/10) -> 0 | J8: =MAX(0,(SUMIF(_計算!$B$2:$B$301,$A8,_計算!$H$2:$H$301)-SUMIF(_計算!$B$2:$B$301,$A8,_計算!$G$2:$G$301))/10) -> 0
A9: P002 | B9: =IFERROR(INDEX(成員名單!$B$5:$B$34,MATCH($A9,成員名單!$A$5:$A$34,0))&"","") | C9: =SUMIF(_計算!$B$2:$B$301,$A9,_計算!$C$2:$C$301)/10 -> 0 | D9: =SUMIF(_計算!$B$2:$B$301,$A9,_計算!$D$2:$D$301)/10 -> 0 | E9: =SUMIF(_計算!$B$2:$B$301,$A9,_計算!$E$2:$E$301)/10 -> 0 | F9: =SUMIF(_計算!$B$2:$B$301,$A9,_計算!$F$2:$F$301)/10 -> 0 | G9: =SUMIF(_計算!$B$2:$B$301,$A9,_計算!$G$2:$G$301)/10 -> 0 | H9: =SUMIF(_計算!$B$2:$B$301,$A9,_計算!$H$2:$H$301)/10 -> 0 | I9: =MAX(0,(SUMIF(_計算!$B$2:$B$301,$A9,_計算!$G$2:$G$301)-SUMIF(_計算!$B$2:$B$301,$A9,_計算!$H$2:$H$301))/10) -> 0 | J9: =MAX(0,(SUMIF(_計算!$B$2:$B$301,$A9,_計算!$H$2:$H$301)-SUMIF(_計算!$B$2:$B$301,$A9,_計算!$G$2:$G$301))/10) -> 0
A10: P003 | B10: =IFERROR(INDEX(成員名單!$B$5:$B$34,MATCH($A10,成員名單!$A$5:$A$34,0))&"","") | C10: =SUMIF(_計算!$B$2:$B$301,$A10,_計算!$C$2:$C$301)/10 -> 0 | D10: =SUMIF(_計算!$B$2:$B$301,$A10,_計算!$D$2:$D$301)/10 -> 0 | E10: =SUMIF(_計算!$B$2:$B$301,$A10,_計算!$E$2:$E$301)/10 -> 0 | F10: =SUMIF(_計算!$B$2:$B$301,$A10,_計算!$F$2:$F$301)/10 -> 0 | G10: =SUMIF(_計算!$B$2:$B$301,$A10,_計算!$G$2:$G$301)/10 -> 0 | H10: =SUMIF(_計算!$B$2:$B$301,$A10,_計算!$H$2:$H$301)/10 -> 0 | I10: =MAX(0,(SUMIF(_計算!$B$2:$B$301,$A10,_計算!$G$2:$G$301)-SUMIF(_計算!$B$2:$B$301,$A10,_計算!$H$2:$H$301))/10) -> 0 | J10: =MAX(0,(SUMIF(_計算!$B$2:$B$301,$A10,_計算!$H$2:$H$301)-SUMIF(_計算!$B$2:$B$301,$A10,_計算!$G$2:$G$301))/10) -> 0
A11: P004 | B11: =IFERROR(INDEX(成員名單!$B$5:$B$34,MATCH($A11,成員名單!$A$5:$A$34,0))&"","") | C11: =SUMIF(_計算!$B$2:$B$301,$A11,_計算!$C$2:$C$301)/10 -> 0 | D11: =SUMIF(_計算!$B$2:$B$301,$A11,_計算!$D$2:$D$301)/10 -> 0 | E11: =SUMIF(_計算!$B$2:$B$301,$A11,_計算!$E$2:$E$301)/10 -> 0 | F11: =SUMIF(_計算!$B$2:$B$301,$A11,_計算!$F$2:$F$301)/10 -> 0 | G11: =SUMIF(_計算!$B$2:$B$301,$A11,_計算!$G$2:$G$301)/10 -> 0 | H11: =SUMIF(_計算!$B$2:$B$301,$A11,_計算!$H$2:$H$301)/10 -> 0 | I11: =MAX(0,(SUMIF(_計算!$B$2:$B$301,$A11,_計算!$G$2:$G$301)-SUMIF(_計算!$B$2:$B$301,$A11,_計算!$H$2:$H$301))/10) -> 0 | J11: =MAX(0,(SUMIF(_計算!$B$2:$B$301,$A11,_計算!$H$2:$H$301)-SUMIF(_計算!$B$2:$B$301,$A11,_計算!$G$2:$G$301))/10) -> 0
A12: P005 | B12: =IFERROR(INDEX(成員名單!$B$5:$B$34,MATCH($A12,成員名單!$A$5:$A$34,0))&"","") | C12: =SUMIF(_計算!$B$2:$B$301,$A12,_計算!$C$2:$C$301)/10 -> 0 | D12: =SUMIF(_計算!$B$2:$B$301,$A12,_計算!$D$2:$D$301)/10 -> 0 | E12: =SUMIF(_計算!$B$2:$B$301,$A12,_計算!$E$2:$E$301)/10 -> 0 | F12: =SUMIF(_計算!$B$2:$B$301,$A12,_計算!$F$2:$F$301)/10 -> 0 | G12: =SUMIF(_計算!$B$2:$B$301,$A12,_計算!$G$2:$G$301)/10 -> 0 | H12: =SUMIF(_計算!$B$2:$B$301,$A12,_計算!$H$2:$H$301)/10 -> 0 | I12: =MAX(0,(SUMIF(_計算!$B$2:$B$301,$A12,_計算!$G$2:$G$301)-SUMIF(_計算!$B$2:$B$301,$A12,_計算!$H$2:$H$301))/10) -> 0 | J12: =MAX(0,(SUMIF(_計算!$B$2:$B$301,$A12,_計算!$H$2:$H$301)-SUMIF(_計算!$B$2:$B$301,$A12,_計算!$G$2:$G$301))/10) -> 0
A13: P006 | B13: =IFERROR(INDEX(成員名單!$B$5:$B$34,MATCH($A13,成員名單!$A$5:$A$34,0))&"","") | C13: =SUMIF(_計算!$B$2:$B$301,$A13,_計算!$C$2:$C$301)/10 -> 0 | D13: =SUMIF(_計算!$B$2:$B$301,$A13,_計算!$D$2:$D$301)/10 -> 0 | E13: =SUMIF(_計算!$B$2:$B$301,$A13,_計算!$E$2:$E$301)/10 -> 0 | F13: =SUMIF(_計算!$B$2:$B$301,$A13,_計算!$F$2:$F$301)/10 -> 0 | G13: =SUMIF(_計算!$B$2:$B$301,$A13,_計算!$G$2:$G$301)/10 -> 0 | H13: =SUMIF(_計算!$B$2:$B$301,$A13,_計算!$H$2:$H$301)/10 -> 0 | I13: =MAX(0,(SUMIF(_計算!$B$2:$B$301,$A13,_計算!$G$2:$G$301)-SUMIF(_計算!$B$2:$B$301,$A13,_計算!$H$2:$H$301))/10) -> 0 | J13: =MAX(0,(SUMIF(_計算!$B$2:$B$301,$A13,_計算!$H$2:$H$301)-SUMIF(_計算!$B$2:$B$301,$A13,_計算!$G$2:$G$301))/10) -> 0
A14: P007 | B14: =IFERROR(INDEX(成員名單!$B$5:$B$34,MATCH($A14,成員名單!$A$5:$A$34,0))&"","") | C14: =SUMIF(_計算!$B$2:$B$301,$A14,_計算!$C$2:$C$301)/10 -> 0 | D14: =SUMIF(_計算!$B$2:$B$301,$A14,_計算!$D$2:$D$301)/10 -> 0 | E14: =SUMIF(_計算!$B$2:$B$301,$A14,_計算!$E$2:$E$301)/10 -> 0 | F14: =SUMIF(_計算!$B$2:$B$301,$A14,_計算!$F$2:$F$301)/10 -> 0 | G14: =SUMIF(_計算!$B$2:$B$301,$A14,_計算!$G$2:$G$301)/10 -> 0 | H14: =SUMIF(_計算!$B$2:$B$301,$A14,_計算!$H$2:$H$301)/10 -> 0 | I14: =MAX(0,(SUMIF(_計算!$B$2:$B$301,$A14,_計算!$G$2:$G$301)-SUMIF(_計算!$B$2:$B$301,$A14,_計算!$H$2:$H$301))/10) -> 0 | J14: =MAX(0,(SUMIF(_計算!$B$2:$B$301,$A14,_計算!$H$2:$H$301)-SUMIF(_計算!$B$2:$B$301,$A14,_計算!$G$2:$G$301))/10) -> 0
A15: P008 | B15: =IFERROR(INDEX(成員名單!$B$5:$B$34,MATCH($A15,成員名單!$A$5:$A$34,0))&"","") | C15: =SUMIF(_計算!$B$2:$B$301,$A15,_計算!$C$2:$C$301)/10 -> 0 | D15: =SUMIF(_計算!$B$2:$B$301,$A15,_計算!$D$2:$D$301)/10 -> 0 | E15: =SUMIF(_計算!$B$2:$B$301,$A15,_計算!$E$2:$E$301)/10 -> 0 | F15: =SUMIF(_計算!$B$2:$B$301,$A15,_計算!$F$2:$F$301)/10 -> 0 | G15: =SUMIF(_計算!$B$2:$B$301,$A15,_計算!$G$2:$G$301)/10 -> 0 | H15: =SUMIF(_計算!$B$2:$B$301,$A15,_計算!$H$2:$H$301)/10 -> 0 | I15: =MAX(0,(SUMIF(_計算!$B$2:$B$301,$A15,_計算!$G$2:$G$301)-SUMIF(_計算!$B$2:$B$301,$A15,_計算!$H$2:$H$301))/10) -> 0 | J15: =MAX(0,(SUMIF(_計算!$B$2:$B$301,$A15,_計算!$H$2:$H$301)-SUMIF(_計算!$B$2:$B$301,$A15,_計算!$G$2:$G$301))/10) -> 0
A16: P009 | B16: =IFERROR(INDEX(成員名單!$B$5:$B$34,MATCH($A16,成員名單!$A$5:$A$34,0))&"","") | C16: =SUMIF(_計算!$B$2:$B$301,$A16,_計算!$C$2:$C$301)/10 -> 0 | D16: =SUMIF(_計算!$B$2:$B$301,$A16,_計算!$D$2:$D$301)/10 -> 0 | E16: =SUMIF(_計算!$B$2:$B$301,$A16,_計算!$E$2:$E$301)/10 -> 0 | F16: =SUMIF(_計算!$B$2:$B$301,$A16,_計算!$F$2:$F$301)/10 -> 0 | G16: =SUMIF(_計算!$B$2:$B$301,$A16,_計算!$G$2:$G$301)/10 -> 0 | H16: =SUMIF(_計算!$B$2:$B$301,$A16,_計算!$H$2:$H$301)/10 -> 0 | I16: =MAX(0,(SUMIF(_計算!$B$2:$B$301,$A16,_計算!$G$2:$G$301)-SUMIF(_計算!$B$2:$B$301,$A16,_計算!$H$2:$H$301))/10) -> 0 | J16: =MAX(0,(SUMIF(_計算!$B$2:$B$301,$A16,_計算!$H$2:$H$301)-SUMIF(_計算!$B$2:$B$301,$A16,_計算!$G$2:$G$301))/10) -> 0
A17: P010 | B17: =IFERROR(INDEX(成員名單!$B$5:$B$34,MATCH($A17,成員名單!$A$5:$A$34,0))&"","") | C17: =SUMIF(_計算!$B$2:$B$301,$A17,_計算!$C$2:$C$301)/10 -> 0 | D17: =SUMIF(_計算!$B$2:$B$301,$A17,_計算!$D$2:$D$301)/10 -> 0 | E17: =SUMIF(_計算!$B$2:$B$301,$A17,_計算!$E$2:$E$301)/10 -> 0 | F17: =SUMIF(_計算!$B$2:$B$301,$A17,_計算!$F$2:$F$301)/10 -> 0 | G17: =SUMIF(_計算!$B$2:$B$301,$A17,_計算!$G$2:$G$301)/10 -> 0 | H17: =SUMIF(_計算!$B$2:$B$301,$A17,_計算!$H$2:$H$301)/10 -> 0 | I17: =MAX(0,(SUMIF(_計算!$B$2:$B$301,$A17,_計算!$G$2:$G$301)-SUMIF(_計算!$B$2:$B$301,$A17,_計算!$H$2:$H$301))/10) -> 0 | J17: =MAX(0,(SUMIF(_計算!$B$2:$B$301,$A17,_計算!$H$2:$H$301)-SUMIF(_計算!$B$2:$B$301,$A17,_計算!$G$2:$G$301))/10) -> 0
A18: P011 | B18: =IFERROR(INDEX(成員名單!$B$5:$B$34,MATCH($A18,成員名單!$A$5:$A$34,0))&"","") | C18: =SUMIF(_計算!$B$2:$B$301,$A18,_計算!$C$2:$C$301)/10 -> 0 | D18: =SUMIF(_計算!$B$2:$B$301,$A18,_計算!$D$2:$D$301)/10 -> 0 | E18: =SUMIF(_計算!$B$2:$B$301,$A18,_計算!$E$2:$E$301)/10 -> 0 | F18: =SUMIF(_計算!$B$2:$B$301,$A18,_計算!$F$2:$F$301)/10 -> 0 | G18: =SUMIF(_計算!$B$2:$B$301,$A18,_計算!$G$2:$G$301)/10 -> 0 | H18: =SUMIF(_計算!$B$2:$B$301,$A18,_計算!$H$2:$H$301)/10 -> 0 | I18: =MAX(0,(SUMIF(_計算!$B$2:$B$301,$A18,_計算!$G$2:$G$301)-SUMIF(_計算!$B$2:$B$301,$A18,_計算!$H$2:$H$301))/10) -> 0 | J18: =MAX(0,(SUMIF(_計算!$B$2:$B$301,$A18,_計算!$H$2:$H$301)-SUMIF(_計算!$B$2:$B$301,$A18,_計算!$G$2:$G$301))/10) -> 0
A19: P012 | B19: =IFERROR(INDEX(成員名單!$B$5:$B$34,MATCH($A19,成員名單!$A$5:$A$34,0))&"","") | C19: =SUMIF(_計算!$B$2:$B$301,$A19,_計算!$C$2:$C$301)/10 -> 0 | D19: =SUMIF(_計算!$B$2:$B$301,$A19,_計算!$D$2:$D$301)/10 -> 0 | E19: =SUMIF(_計算!$B$2:$B$301,$A19,_計算!$E$2:$E$301)/10 -> 0 | F19: =SUMIF(_計算!$B$2:$B$301,$A19,_計算!$F$2:$F$301)/10 -> 0 | G19: =SUMIF(_計算!$B$2:$B$301,$A19,_計算!$G$2:$G$301)/10 -> 0 | H19: =SUMIF(_計算!$B$2:$B$301,$A19,_計算!$H$2:$H$301)/10 -> 0 | I19: =MAX(0,(SUMIF(_計算!$B$2:$B$301,$A19,_計算!$G$2:$G$301)-SUMIF(_計算!$B$2:$B$301,$A19,_計算!$H$2:$H$301))/10) -> 0 | J19: =MAX(0,(SUMIF(_計算!$B$2:$B$301,$A19,_計算!$H$2:$H$301)-SUMIF(_計算!$B$2:$B$301,$A19,_計算!$G$2:$G$301))/10) -> 0
... A37: P030 | B37: =IFERROR(INDEX(成員名單!$B$5:$B$34,MATCH($A37,成員名單!$A$5:$A$34,0))&"","") | C37: =SUMIF(_計算!$B$2:$B$301,$A37,_計算!$C$2:$C$301)/10 -> 0 | D37: =SUMIF(_計算!$B$2:$B$301,$A37,_計算!$D$2:$D$301)/10 -> 0 | E37: =SUMIF(_計算!$B$2:$B$301,$A37,_計算!$E$2:$E$301)/10 -> 0 | F37: =SUMIF(_計算!$B$2:$B$301,$A37,_計算!$F$2:$F$301)/10 -> 0 | G37: =SUMIF(_計算!$B$2:$B$301,$A37,_計算!$G$2:$G$301)/10 -> 0 | H37: =SUMIF(_計算!$B$2:$B$301,$A37,_計算!$H$2:$H$301)/10 -> 0 | I37: =MAX(0,(SUMIF(_計算!$B$2:$B$301,$A37,_計算!$G$2:$G$301)-SUMIF(_計算!$B$2:$B$301,$A37,_計算!$H$2:$H$301))/10) -> 0 | J37: =MAX(0,(SUMIF(_計算!$B$2:$B$301,$A37,_計算!$H$2:$H$301)-SUMIF(_計算!$B$2:$B$301,$A37,_計算!$G$2:$G$301))/10) -> 0
B38: 合計 | C38: =SUM(_計算!C2:C301)/10 -> 0 | D38: =SUM(_計算!D2:D301)/10 -> 0 | E38: =SUM(_計算!E2:E301)/10 -> 0 | F38: =SUM(_計算!F2:F301)/10 -> 0 | G38: =SUM(_計算!G2:G301)/10 -> 0 | H38: =SUM(_計算!H2:H301)/10 -> 0 | I38: =SUM(MAX(0,SUMIF(_計算!$B$2:$B$301,$A8,_計算!$G$2:$G$301)-SUMIF(_計算!$B$2:$B$301,$A8,_計算!$H$2:$H$301)),MAX(0,SUMIF(_計算!$B$2:$B$301,$A9,_計算!$G$2:$G$301)-SUMIF(_計算!$B$2:$B$301,$A9,_計算!$H$2:$H$301)),MAX(0,SUMIF(_計算!$B$2:$B$301,$A10,_計算!$G$2:$G$301)-SUMIF(_計算!$B$2:$B$301,$A10,_計算!$H$2:$H$301)),MAX(0,SUMIF(_計算!$B$2:$B$301,$A11,_計算!$G$2:$G$301)-SUMIF(_計算!$B$2:$B$301,$A11,_計算!$H$2:$H$301)),MAX(0,SUMIF(_計算!$B$2:$B$301,$A12,_計算!$G$2:$G$301)-SUMIF(_計算!$B$2:$B$301,$A12,_計算!$H$2:$H$301)),MAX(0,SUMIF(_計算!$B$2:$B$301,$A13,_計算!$G$2:$G$301)-SUMIF(_計算!$B$2:$B$301,$A13,_計算!$H$2:$H$301)),MAX(0,SUMIF(_計算!$B$2:$B$301,$A14,_計算!$G$2:$G$301)-SUMIF(_計算!$B$2:$B$301,$A14,_計算!$H$2:$H$301)),MAX(0,SUMIF(_計算!$B$2:$B$301,$A15,_計算!$G$2:$G$301)-SUMIF(_計算!$B$2:$B$301,$A15,_計算!$H$2:$H$301)),MAX(0,SUMIF(_計算!$B$2:$B$301,$A16,_計算!$G$2:$G$301)-SUMIF(_計算!$B$2:$B$301,$A16,_計算!$H$2:$H$301)),MAX(0,SUMIF(_計算!$B$2:$B$301,$A17,_計算!$G$2:$G$301)-SUMIF(_計算!$B$2:$B$301,$A17,_計算!$H$2:$H$301)),MAX(0,SUMIF(_計算!$B$2:$B$301,$A18,_計算!$G$2:$G$301)-SUMIF(_計算!$B$2:$B$301,$A18,_計算!$H$2:$H$301)),MAX(0,SUMIF(_計算!$B$2:$B$301,$A19,_計算!$G$2:$G$301)-SUMIF(_計算!$B$2:$B$301,$A19,_計算!$H$2:$H$301)),MAX(0,SUMIF(_計算!$B$2:$B$301,$A20,_計算!$G$2:$G$301)-SUMIF(_計算!$B$2:$B$301,$A20,_計算!$H$2:$H$301)),MAX(0,SUMIF(_計算!$B$2:$B$301,$A21,_計算!$G$2:$G$301)-SUMIF(_計算!$B$2:$B$301,$A21,_計算!$H$2:$H$301)),MAX(0,SUMIF(_計算!$B$2:$B$301,$A22,_計算!$G$2:$G$301)-SUMIF(_計算!$B$2:$B$301,$A22,_計算!$H$2:$H$301)),MAX(0,SUMIF(_計算!$B$2:$B$301,$A23,_計算!$G$2:$G$301)-SUMIF(_計算!$B$2:$B$301,$A23,_計算!$H$2:$H$301)),MAX(0,SUMIF(_計算!$B$2:$B$301,$A24,_計算!$G$2:$G$301)-SUMIF(_計算!$B$2:$B$301,$A24,_計算!$H$2:$H$301)),MAX(0,SUMIF(_計算!$B$2:$B$301,$A25,_計算!$G$2:$G$301)-SUMIF(_計算!$B$2:$B$301,$A25,_計算!$H$2:$H$301)),MAX(0,SUMIF(_計算!$B$2:$B$301,$A26,_計算!$G$2:$G$301)-SUMIF(_計算!$B$2:$B$301,$A26,_計算!$H$2:$H$301)),MAX(0,SUMIF(_計算!$B$2:$B$301,$A27,_計算!$G$2:$G$301)-SUMIF(_計算!$B$2:$B$301,$A27,_計算!$H$2:$H$301)),MAX(0,SUMIF(_計算!$B$2:$B$301,$A28,_計算!$G$2:$G$301)-SUMIF(_計算!$B$2:$B$301,$A28,_計算!$H$2:$H$301)),MAX(0,SUMIF(_計算!$B$2:$B$301,$A29,_計算!$G$2:$G$301)-SUMIF(_計算!$B$2:$B$301,$A29,_計算!$H$2:$H$301)),MAX(0,SUMIF(_計算!$B$2:$B$301,$A30,_計算!$G$2:$G$301)-SUMIF(_計算!$B$2:$B$301,$A30,_計算!$H$2:$H$301)),MAX(0,SUMIF(_計算!$B$2:$B$301,$A31,_計算!$G$2:$G$301)-SUMIF(_計算!$B$2:$B$301,$A31,_計算!$H$2:$H$301)),MAX(0,SUMIF(_計算!$B$2:$B$301,$A32,_計算!$G$2:$G$301)-SUMIF(_計算!$B$2:$B$301,$A32,_計算!$H$2:$H$301)),MAX(0,SUMIF(_計算!$B$2:$B$301,$A33,_計算!$G$2:$G$301)-SUMIF(_計算!$B$2:$B$301,$A33,_計算!$H$2:$H$301)),MAX(0,SUMIF(_計算!$B$2:$B$301,$A34,_計算!$G$2:$G$301)-SUMIF(_計算!$B$2:$B$301,$A34,_計算!$H$2:$H$301)),MAX(0,SUMIF(_計算!$B$2:$B$301,$A35,_計算!$G$2:$G$301)-SUMIF(_計算!$B$2:$B$301,$A35,_計算!$H$2:$H$301)),MAX(0,SUMIF(_計算!$B$2:$B$301,$A36,_計算!$G$2:$G$301)-SUMIF(_計算!$B$2:$B$301,$A36,_計算!$H$2:$H$301)),MAX(0,SUMIF(_計算!$B$2:$B$301,$A37,_計算!$G$2:$G$301)-SUMIF(_計算!$B$2:$B$301,$A37,_計算!$H$2:$H$301)))/10 -> 0 | J38: =SUM(MAX(0,SUMIF(_計算!$B$2:$B$301,$A8,_計算!$H$2:$H$301)-SUMIF(_計算!$B$2:$B$301,$A8,_計算!$G$2:$G$301)),MAX(0,SUMIF(_計算!$B$2:$B$301,$A9,_計算!$H$2:$H$301)-SUMIF(_計算!$B$2:$B$301,$A9,_計算!$G$2:$G$301)),MAX(0,SUMIF(_計算!$B$2:$B$301,$A10,_計算!$H$2:$H$301)-SUMIF(_計算!$B$2:$B$301,$A10,_計算!$G$2:$G$301)),MAX(0,SUMIF(_計算!$B$2:$B$301,$A11,_計算!$H$2:$H$301)-SUMIF(_計算!$B$2:$B$301,$A11,_計算!$G$2:$G$301)),MAX(0,SUMIF(_計算!$B$2:$B$301,$A12,_計算!$H$2:$H$301)-SUMIF(_計算!$B$2:$B$301,$A12,_計算!$G$2:$G$301)),MAX(0,SUMIF(_計算!$B$2:$B$301,$A13,_計算!$H$2:$H$301)-SUMIF(_計算!$B$2:$B$301,$A13,_計算!$G$2:$G$301)),MAX(0,SUMIF(_計算!$B$2:$B$301,$A14,_計算!$H$2:$H$301)-SUMIF(_計算!$B$2:$B$301,$A14,_計算!$G$2:$G$301)),MAX(0,SUMIF(_計算!$B$2:$B$301,$A15,_計算!$H$2:$H$301)-SUMIF(_計算!$B$2:$B$301,$A15,_計算!$G$2:$G$301)),MAX(0,SUMIF(_計算!$B$2:$B$301,$A16,_計算!$H$2:$H$301)-SUMIF(_計算!$B$2:$B$301,$A16,_計算!$G$2:$G$301)),MAX(0,SUMIF(_計算!$B$2:$B$301,$A17,_計算!$H$2:$H$301)-SUMIF(_計算!$B$2:$B$301,$A17,_計算!$G$2:$G$301)),MAX(0,SUMIF(_計算!$B$2:$B$301,$A18,_計算!$H$2:$H$301)-SUMIF(_計算!$B$2:$B$301,$A18,_計算!$G$2:$G$301)),MAX(0,SUMIF(_計算!$B$2:$B$301,$A19,_計算!$H$2:$H$301)-SUMIF(_計算!$B$2:$B$301,$A19,_計算!$G$2:$G$301)),MAX(0,SUMIF(_計算!$B$2:$B$301,$A20,_計算!$H$2:$H$301)-SUMIF(_計算!$B$2:$B$301,$A20,_計算!$G$2:$G$301)),MAX(0,SUMIF(_計算!$B$2:$B$301,$A21,_計算!$H$2:$H$301)-SUMIF(_計算!$B$2:$B$301,$A21,_計算!$G$2:$G$301)),MAX(0,SUMIF(_計算!$B$2:$B$301,$A22,_計算!$H$2:$H$301)-SUMIF(_計算!$B$2:$B$301,$A22,_計算!$G$2:$G$301)),MAX(0,SUMIF(_計算!$B$2:$B$301,$A23,_計算!$H$2:$H$301)-SUMIF(_計算!$B$2:$B$301,$A23,_計算!$G$2:$G$301)),MAX(0,SUMIF(_計算!$B$2:$B$301,$A24,_計算!$H$2:$H$301)-SUMIF(_計算!$B$2:$B$301,$A24,_計算!$G$2:$G$301)),MAX(0,SUMIF(_計算!$B$2:$B$301,$A25,_計算!$H$2:$H$301)-SUMIF(_計算!$B$2:$B$301,$A25,_計算!$G$2:$G$301)),MAX(0,SUMIF(_計算!$B$2:$B$301,$A26,_計算!$H$2:$H$301)-SUMIF(_計算!$B$2:$B$301,$A26,_計算!$G$2:$G$301)),MAX(0,SUMIF(_計算!$B$2:$B$301,$A27,_計算!$H$2:$H$301)-SUMIF(_計算!$B$2:$B$301,$A27,_計算!$G$2:$G$301)),MAX(0,SUMIF(_計算!$B$2:$B$301,$A28,_計算!$H$2:$H$301)-SUMIF(_計算!$B$2:$B$301,$A28,_計算!$G$2:$G$301)),MAX(0,SUMIF(_計算!$B$2:$B$301,$A29,_計算!$H$2:$H$301)-SUMIF(_計算!$B$2:$B$301,$A29,_計算!$G$2:$G$301)),MAX(0,SUMIF(_計算!$B$2:$B$301,$A30,_計算!$H$2:$H$301)-SUMIF(_計算!$B$2:$B$301,$A30,_計算!$G$2:$G$301)),MAX(0,SUMIF(_計算!$B$2:$B$301,$A31,_計算!$H$2:$H$301)-SUMIF(_計算!$B$2:$B$301,$A31,_計算!$G$2:$G$301)),MAX(0,SUMIF(_計算!$B$2:$B$301,$A32,_計算!$H$2:$H$301)-SUMIF(_計算!$B$2:$B$301,$A32,_計算!$G$2:$G$301)),MAX(0,SUMIF(_計算!$B$2:$B$301,$A33,_計算!$H$2:$H$301)-SUMIF(_計算!$B$2:$B$301,$A33,_計算!$G$2:$G$301)),MAX(0,SUMIF(_計算!$B$2:$B$301,$A34,_計算!$H$2:$H$301)-SUMIF(_計算!$B$2:$B$301,$A34,_計算!$G$2:$G$301)),MAX(0,SUMIF(_計算!$B$2:$B$301,$A35,_計算!$H$2:$H$301)-SUMIF(_計算!$B$2:$B$301,$A35,_計算!$G$2:$G$301)),MAX(0,SUMIF(_計算!$B$2:$B$301,$A36,_計算!$H$2:$H$301)-SUMIF(_計算!$B$2:$B$301,$A36,_計算!$G$2:$G$301)),MAX(0,SUMIF(_計算!$B$2:$B$301,$A37,_計算!$H$2:$H$301)-SUMIF(_計算!$B$2:$B$301,$A37,_計算!$G$2:$G$301)))/10 -> 0
B41: 費用核對清單（同筆多個提醒計為一筆待處理）
B42: 日期 | C42: 費用 | D42: 總金額 | E42: 待處理提醒
B43: ='第 1 天'!$B$2 -> 第 1 天 | C43: ='第 1 天'!D4 -> 早餐 | D43: ='第 1 天'!D46/10 -> 0 | E43: ='第 1 天'!D10
B44: ='第 1 天'!$B$2 -> 第 1 天 | C44: ='第 1 天'!F4 -> 午餐 | D44: ='第 1 天'!F46/10 -> 0 | E44: ='第 1 天'!F10
B45: ='第 1 天'!$B$2 -> 第 1 天 | C45: ='第 1 天'!H4 -> 晚餐 | D45: ='第 1 天'!H46/10 -> 0 | E45: ='第 1 天'!H10
B46: ='第 1 天'!$B$2 -> 第 1 天 | C46: ='第 1 天'!J4 -> 油錢 | D46: ='第 1 天'!J46/10 -> 0 | E46: ='第 1 天'!J10
B47: ='第 1 天'!$B$2 -> 第 1 天 | C47: ='第 1 天'!L4 -> 租車費 | D47: ='第 1 天'!L46/10 -> 0 | E47: ='第 1 天'!L10
B48: ='第 1 天'!$B$2 -> 第 1 天 | C48: ='第 1 天'!N4 -> 停車費 | D48: ='第 1 天'!N46/10 -> 0 | E48: ='第 1 天'!N10
B49: ='第 1 天'!$B$2 -> 第 1 天 | C49: ='第 1 天'!P4 -> 其他 | D49: ='第 1 天'!P46/10 -> 0 | E49: ='第 1 天'!P10
B50: ='第 2 天'!$B$2 -> 第 2 天 | C50: ='第 2 天'!D4 -> 早餐 | D50: ='第 2 天'!D46/10 -> 0 | E50: ='第 2 天'!D10
B51: ='第 2 天'!$B$2 -> 第 2 天 | C51: ='第 2 天'!F4 -> 午餐 | D51: ='第 2 天'!F46/10 -> 0 | E51: ='第 2 天'!F10
B52: ='第 2 天'!$B$2 -> 第 2 天 | C52: ='第 2 天'!H4 -> 晚餐 | D52: ='第 2 天'!H46/10 -> 0 | E52: ='第 2 天'!H10
B53: ='第 2 天'!$B$2 -> 第 2 天 | C53: ='第 2 天'!J4 -> 油錢 | D53: ='第 2 天'!J46/10 -> 0 | E53: ='第 2 天'!J10
B54: ='第 2 天'!$B$2 -> 第 2 天 | C54: ='第 2 天'!L4 -> 租車費 | D54: ='第 2 天'!L46/10 -> 0 | E54: ='第 2 天'!L10
B55: ='第 2 天'!$B$2 -> 第 2 天 | C55: ='第 2 天'!N4 -> 停車費 | D55: ='第 2 天'!N46/10 -> 0 | E55: ='第 2 天'!N10
B56: ='第 2 天'!$B$2 -> 第 2 天 | C56: ='第 2 天'!P4 -> 其他 | D56: ='第 2 天'!P46/10 -> 0 | E56: ='第 2 天'!P10
B57: ='第 3 天'!$B$2 -> 第 3 天 | C57: ='第 3 天'!D4 -> 早餐 | D57: ='第 3 天'!D46/10 -> 0 | E57: ='第 3 天'!D10
B58: ='第 3 天'!$B$2 -> 第 3 天 | C58: ='第 3 天'!F4 -> 午餐 | D58: ='第 3 天'!F46/10 -> 0 | E58: ='第 3 天'!F10
B59: ='第 3 天'!$B$2 -> 第 3 天 | C59: ='第 3 天'!H4 -> 晚餐 | D59: ='第 3 天'!H46/10 -> 0 | E59: ='第 3 天'!H10
B60: ='第 3 天'!$B$2 -> 第 3 天 | C60: ='第 3 天'!J4 -> 油錢 | D60: ='第 3 天'!J46/10 -> 0 | E60: ='第 3 天'!J10
...

Sheet 成員名單
B1: 統一成員名單
B2: 只修改姓名；固定 ID 請勿修改。增減成員請用「旅伴帳本」選單。
A4: 固定 ID | B4: 姓名 | C4: 使用說明
A5: P001 | C5: 空白姓名不分攤
A6: P002 | C6: 空白姓名不分攤
A7: P003 | C7: 空白姓名不分攤
A8: P004 | C8: 空白姓名不分攤
A9: P005 | C9: 空白姓名不分攤
A10: P006 | C10: 空白姓名不分攤
A11: P007 | C11: 空白姓名不分攤
A12: P008 | C12: 空白姓名不分攤
A13: P009 | C13: 空白姓名不分攤
A14: P010 | C14: 空白姓名不分攤
A15: P011 | C15: 空白姓名不分攤
A16: P012 | C16: 空白姓名不分攤
... A34: P030 | C34: 空白姓名不分攤

Sheet 第 1 天
A1: d_mveoqnqvyb0rn2635 | D1: e_mveoqnqvjz2s9ftem | F1: e_mveoqnqvdelrgp3xm | H1: e_mveoqnqvfsq21n0ln | J1: e_mveoqnqvs3pz1ky6s | L1: e_mveoqnqv08ss7dizj | N1: e_mveoqnqvrbr1s3nzo | P1: e_mveoqnqvspu97fddj
B2: 第 1 天 | D2: 全選／取消全選：選取費用欄後使用「旅伴帳本」選單。
B3: 當日用車 | C3: =FALSE() -> FALSE | D3: 司機只免當日油錢與租車費；餐費、停車費與其他正常分攤。
B4: 名稱 | D4: 早餐 | F4: 午餐 | H4: 晚餐 | J4: 油錢 | L4: 租車費 | N4: 停車費 | P4: 其他
B5: 類別 | D5: 早餐 | F5: 午餐 | H5: 晚餐 | J5: 油錢 | L5: 租車費 | N5: 停車費 | P5: 其他
B6: 總金額（元） | E6: 元 | G6: 元 | I6: 元 | K6: 元 | M6: 元 | O6: 元 | Q6: 元
B7: 代墊者 ID | E7: =IFERROR(INDEX(成員名單!$B$5:$B$34,MATCH(D7,成員名單!$A$5:$A$34,0))&"","") | G7: =IFERROR(INDEX(成員名單!$B$5:$B$34,MATCH(F7,成員名單!$A$5:$A$34,0))&"","") | I7: =IFERROR(INDEX(成員名單!$B$5:$B$34,MATCH(H7,成員名單!$A$5:$A$34,0))&"","") | K7: =IFERROR(INDEX(成員名單!$B$5:$B$34,MATCH(J7,成員名單!$A$5:$A$34,0))&"","") | M7: =IFERROR(INDEX(成員名單!$B$5:$B$34,MATCH(L7,成員名單!$A$5:$A$34,0))&"","") | O7: =IFERROR(INDEX(成員名單!$B$5:$B$34,MATCH(N7,成員名單!$A$5:$A$34,0))&"","") | Q7: =IFERROR(INDEX(成員名單!$B$5:$B$34,MATCH(P7,成員名單!$A$5:$A$34,0))&"","")
B8: 分攤人數 | D8: =IF(D$47,D$48,0) -> 0 | E8: 人 | F8: =IF(F$47,F$48,0) -> 0 | G8: 人 | H8: =IF(H$47,H$48,0) -> 0 | I8: 人 | J8: =IF(J$47,J$48,0) -> 0 | K8: 人 | L8: =IF(L$47,L$48,0) -> 0 | M8: 人 | N8: =IF(N$47,N$48,0) -> 0 | O8: 人 | P8: =IF(P$47,P$48,0) -> 0 | Q8: 人
B9: 每人金額範圍 | D9: =IF(OR(NOT(D$47),D$48=0),"暫不分攤",TEXT(QUOTIENT(D$46,MAX(1,D$48))/10,"0.0")&IF(MOD(D$46,MAX(1,D$48))>0,"–"&TEXT((QUOTIENT(D$46,MAX(1,D$48))+1)/10,"0.0"),"")&" 元／人") -> 暫不分攤 | F9: =IF(OR(NOT(F$47),F$48=0),"暫不分攤",TEXT(QUOTIENT(F$46,MAX(1,F$48))/10,"0.0")&IF(MOD(F$46,MAX(1,F$48))>0,"–"&TEXT((QUOTIENT(F$46,MAX(1,F$48))+1)/10,"0.0"),"")&" 元／人") -> 暫不分攤 | H9: =IF(OR(NOT(H$47),H$48=0),"暫不分攤",TEXT(QUOTIENT(H$46,MAX(1,H$48))/10,"0.0")&IF(MOD(H$46,MAX(1,H$48))>0,"–"&TEXT((QUOTIENT(H$46,MAX(1,H$48))+1)/10,"0.0"),"")&" 元／人") -> 暫不分攤 | J9: =IF(OR(NOT(J$47),J$48=0),"暫不分攤",TEXT(QUOTIENT(J$46,MAX(1,J$48))/10,"0.0")&IF(MOD(J$46,MAX(1,J$48))>0,"–"&TEXT((QUOTIENT(J$46,MAX(1,J$48))+1)/10,"0.0"),"")&" 元／人") -> 暫不分攤 | L9: =IF(OR(NOT(L$47),L$48=0),"暫不分攤",TEXT(QUOTIENT(L$46,MAX(1,L$48))/10,"0.0")&IF(MOD(L$46,MAX(1,L$48))>0,"–"&TEXT((QUOTIENT(L$46,MAX(1,L$48))+1)/10,"0.0"),"")&" 元／人") -> 暫不分攤 | N9: =IF(OR(NOT(N$47),N$48=0),"暫不分攤",TEXT(QUOTIENT(N$46,MAX(1,N$48))/10,"0.0")&IF(MOD(N$46,MAX(1,N$48))>0,"–"&TEXT((QUOTIENT(N$46,MAX(1,N$48))+1)/10,"0.0"),"")&" 元／人") -> 暫不分攤 | P9: =IF(OR(NOT(P$47),P$48=0),"暫不分攤",TEXT(QUOTIENT(P$46,MAX(1,P$48))/10,"0.0")&IF(MOD(P$46,MAX(1,P$48))>0,"–"&TEXT((QUOTIENT(P$46,MAX(1,P$48))+1)/10,"0.0"),"")&" 元／人") -> 暫不分攤
B10: 待處理提醒 | D10: =IF(NOT(D$47),"金額須為非負數且最多一位小數。 ","")&IF(AND(D$46>0,D$50,$C$3<>TRUE()),"未用車但有車資：保留金額，暫不分攤。 ","")&IF(AND(D$46>0,D$50,$C$3=TRUE(),$C$49=0),"請設定具名司機；車資暫不分攤。 ","")&IF(AND(D$46>0,D$48=0,NOT(AND(D$46>0,D$50,$C$3<>TRUE())),NOT(AND(D$46>0,D$50,$C$3=TRUE(),$C$49=0))),"沒有可分攤者。 ","")&IF(AND(D$46>0,LEN(TRIM(E7))=0),"請指定具名代墊者。","") | F10: =IF(NOT(F$47),"金額須為非負數且最多一位小數。 ","")&IF(AND(F$46>0,F$50,$C$3<>TRUE()),"未用車但有車資：保留金額，暫不分攤。 ","")&IF(AND(F$46>0,F$50,$C$3=TRUE(),$C$49=0),"請設定具名司機；車資暫不分攤。 ","")&IF(AND(F$46>0,F$48=0,NOT(AND(F$46>0,F$50,$C$3<>TRUE())),NOT(AND(F$46>0,F$50,$C$3=TRUE(),$C$49=0))),"沒有可分攤者。 ","")&IF(AND(F$46>0,LEN(TRIM(G7))=0),"請指定具名代墊者。","") | H10: =IF(NOT(H$47),"金額須為非負數且最多一位小數。 ","")&IF(AND(H$46>0,H$50,$C$3<>TRUE()),"未用車但有車資：保留金額，暫不分攤。 ","")&IF(AND(H$46>0,H$50,$C$3=TRUE(),$C$49=0),"請設定具名司機；車資暫不分攤。 ","")&IF(AND(H$46>0,H$48=0,NOT(AND(H$46>0,H$50,$C$3<>TRUE())),NOT(AND(H$46>0,H$50,$C$3=TRUE(),$C$49=0))),"沒有可分攤者。 ","")&IF(AND(H$46>0,LEN(TRIM(I7))=0),"請指定具名代墊者。","") | J10: =IF(NOT(J$47),"金額須為非負數且最多一位小數。 ","")&IF(AND(J$46>0,J$50,$C$3<>TRUE()),"未用車但有車資：保留金額，暫不分攤。 ","")&IF(AND(J$46>0,J$50,$C$3=TRUE(),$C$49=0),"請設定具名司機；車資暫不分攤。 ","")&IF(AND(J$46>0,J$48=0,NOT(AND(J$46>0,J$50,$C$3<>TRUE())),NOT(AND(J$46>0,J$50,$C$3=TRUE(),$C$49=0))),"沒有可分攤者。 ","")&IF(AND(J$46>0,LEN(TRIM(K7))=0),"請指定具名代墊者。","") | L10: =IF(NOT(L$47),"金額須為非負數且最多一位小數。 ","")&IF(AND(L$46>0,L$50,$C$3<>TRUE()),"未用車但有車資：保留金額，暫不分攤。 ","")&IF(AND(L$46>0,L$50,$C$3=TRUE(),$C$49=0),"請設定具名司機；車資暫不分攤。 ","")&IF(AND(L$46>0,L$48=0,NOT(AND(L$46>0,L$50,$C$3<>TRUE())),NOT(AND(L$46>0,L$50,$C$3=TRUE(),$C$49=0))),"沒有可分攤者。 ","")&IF(AND(L$46>0,LEN(TRIM(M7))=0),"請指定具名代墊者。","") | N10: =IF(NOT(N$47),"金額須為非負數且最多一位小數。 ","")&IF(AND(N$46>0,N$50,$C$3<>TRUE()),"未用車但有車資：保留金額，暫不分攤。 ","")&IF(AND(N$46>0,N$50,$C$3=TRUE(),$C$49=0),"請設定具名司機；車資暫不分攤。 ","")&IF(AND(N$46>0,N$48=0,NOT(AND(N$46>0,N$50,$C$3<>TRUE())),NOT(AND(N$46>0,N$50,$C$3=TRUE(),$C$49=0))),"沒有可分攤者。 ","")&IF(AND(N$46>0,LEN(TRIM(O7))=0),"請指定具名代墊者。","") | P10: =IF(NOT(P$47),"金額須為非負數且最多一位小數。 ","")&IF(AND(P$46>0,P$50,$C$3<>TRUE()),"未用車但有車資：保留金額，暫不分攤。 ","")&IF(AND(P$46>0,P$50,$C$3=TRUE(),$C$49=0),"請設定具名司機；車資暫不分攤。 ","")&IF(AND(P$46>0,P$48=0,NOT(AND(P$46>0,P$50,$C$3<>TRUE())),NOT(AND(P$46>0,P$50,$C$3=TRUE(),$C$49=0))),"沒有可分攤者。 ","")&IF(AND(P$46>0,LEN(TRIM(Q7))=0),"請指定具名代墊者。","")
A11: 固定 ID | B11: 姓名 | C11: 當日司機 | D11: 是否參與 | E11: 分攤（元） | F11: 是否參與 | G11: 分攤（元） | H11: 是否參與 | I11: 分攤（元） | J11: 是否參與 | K11: 分攤（元） | L11: 是否參與 | M11: 分攤（元） | N11: 是否參與 | O11: 分攤（元） | P11: 是否參與 | Q11: 分攤（元）
A12: P001 | B12: =IFERROR(INDEX(成員名單!$B$5:$B$34,MATCH($A12,成員名單!$A$5:$A$34,0))&"","") | C12: =FALSE() -> FALSE | D12: =FALSE() -> FALSE | E12: =D52/10 -> 0 | F12: =FALSE() -> FALSE | G12: =F52/10 -> 0 | H12: =FALSE() -> FALSE | I12: =H52/10 -> 0 | J12: =FALSE() -> FALSE | K12: =J52/10 -> 0 | L12: =FALSE() -> FALSE | M12: =L52/10 -> 0 | N12: =FALSE() -> FALSE | O12: =N52/10 -> 0 | P12: =FALSE() -> FALSE | Q12: =P52/10 -> 0
A13: P002 | B13: =IFERROR(INDEX(成員名單!$B$5:$B$34,MATCH($A13,成員名單!$A$5:$A$34,0))&"","") | C13: =FALSE() -> FALSE | D13: =FALSE() -> FALSE | E13: =D53/10 -> 0 | F13: =FALSE() -> FALSE | G13: =F53/10 -> 0 | H13: =FALSE() -> FALSE | I13: =H53/10 -> 0 | J13: =FALSE() -> FALSE | K13: =J53/10 -> 0 | L13: =FALSE() -> FALSE | M13: =L53/10 -> 0 | N13: =FALSE() -> FALSE | O13: =N53/10 -> 0 | P13: =FALSE() -> FALSE | Q13: =P53/10 -> 0
A14: P003 | B14: =IFERROR(INDEX(成員名單!$B$5:$B$34,MATCH($A14,成員名單!$A$5:$A$34,0))&"","") | C14: =FALSE() -> FALSE | D14: =FALSE() -> FALSE | E14: =D54/10 -> 0 | F14: =FALSE() -> FALSE | G14: =F54/10 -> 0 | H14: =FALSE() -> FALSE | I14: =H54/10 -> 0 | J14: =FALSE() -> FALSE | K14: =J54/10 -> 0 | L14: =FALSE() -> FALSE | M14: =L54/10 -> 0 | N14: =FALSE() -> FALSE | O14: =N54/10 -> 0 | P14: =FALSE() -> FALSE | Q14: =P54/10 -> 0
A15: P004 | B15: =IFERROR(INDEX(成員名單!$B$5:$B$34,MATCH($A15,成員名單!$A$5:$A$34,0))&"","") | C15: =FALSE() -> FALSE | D15: =FALSE() -> FALSE | E15: =D55/10 -> 0 | F15: =FALSE() -> FALSE | G15: =F55/10 -> 0 | H15: =FALSE() -> FALSE | I15: =H55/10 -> 0 | J15: =FALSE() -> FALSE | K15: =J55/10 -> 0 | L15: =FALSE() -> FALSE | M15: =L55/10 -> 0 | N15: =FALSE() -> FALSE | O15: =N55/10 -> 0 | P15: =FALSE() -> FALSE | Q15: =P55/10 -> 0
A16: P005 | B16: =IFERROR(INDEX(成員名單!$B$5:$B$34,MATCH($A16,成員名單!$A$5:$A$34,0))&"","") | C16: =FALSE() -> FALSE | D16: =FALSE() -> FALSE | E16: =D56/10 -> 0 | F16: =FALSE() -> FALSE | G16: =F56/10 -> 0 | H16: =FALSE() -> FALSE | I16: =H56/10 -> 0 | J16: =FALSE() -> FALSE | K16: =J56/10 -> 0 | L16: =FALSE() -> FALSE | M16: =L56/10 -> 0 | N16: =FALSE() -> FALSE | O16: =N56/10 -> 0 | P16: =FALSE() -> FALSE | Q16: =P56/10 -> 0
A17: P006 | B17: =IFERROR(INDEX(成員名單!$B$5:$B$34,MATCH($A17,成員名單!$A$5:$A$34,0))&"","") | C17: =FALSE() -> FALSE | D17: =FALSE() -> FALSE | E17: =D57/10 -> 0 | F17: =FALSE() -> FALSE | G17: =F57/10 -> 0 | H17: =FALSE() -> FALSE | I17: =H57/10 -> 0 | J17: =FALSE() -> FALSE | K17: =J57/10 -> 0 | L17: =FALSE() -> FALSE | M17: =L57/10 -> 0 | N17: =FALSE() -> FALSE | O17: =N57/10 -> 0 | P17: =FALSE() -> FALSE | Q17: =P57/10 -> 0
A18: P007 | B18: =IFERROR(INDEX(成員名單!$B$5:$B$34,MATCH($A18,成員名單!$A$5:$A$34,0))&"","") | C18: =FALSE() -> FALSE | D18: =FALSE() -> FALSE | E18: =D58/10 -> 0 | F18: =FALSE() -> FALSE | G18: =F58/10 -> 0 | H18: =FALSE() -> FALSE | I18: =H58/10 -> 0 | J18: =FALSE() -> FALSE | K18: =J58/10 -> 0 | L18: =FALSE() -> FALSE | M18: =L58/10 -> 0 | N18: =FALSE() -> FALSE | O18: =N58/10 -> 0 | P18: =FALSE() -> FALSE | Q18: =P58/10 -> 0
A19: P008 | B19: =IFERROR(INDEX(成員名單!$B$5:$B$34,MATCH($A19,成員名單!$A$5:$A$34,0))&"","") | C19: =FALSE() -> FALSE | D19: =FALSE() -> FALSE | E19: =D59/10 -> 0 | F19: =FALSE() -> FALSE | G19: =F59/10 -> 0 | H19: =FALSE() -> FALSE | I19: =H59/10 -> 0 | J19: =FALSE() -> FALSE | K19: =J59/10 -> 0 | L19: =FALSE() -> FALSE | M19: =L59/10 -> 0 | N19: =FALSE() -> FALSE | O19: =N59/10 -> 0 | P19: =FALSE() -> FALSE | Q19: =P59/10 -> 0
A20: P009 | B20: =IFERROR(INDEX(成員名單!$B$5:$B$34,MATCH($A20,成員名單!$A$5:$A$34,0))&"","") | C20: =FALSE() -> FALSE | D20: =FALSE() -> FALSE | E20: =D60/10 -> 0 | F20: =FALSE() -> FALSE | G20: =F60/10 -> 0 | H20: =FALSE() -> FALSE | I20: =H60/10 -> 0 | J20: =FALSE() -> FALSE | K20: =J60/10 -> 0 | L20: =FALSE() -> FALSE | M20: =L60/10 -> 0 | N20: =FALSE() -> FALSE | O20: =N60/10 -> 0 | P20: =FALSE() -> FALSE | Q20: =P60/10 -> 0
A21: P010 | B21: =IFERROR(INDEX(成員名單!$B$5:$B$34,MATCH($A21,成員名單!$A$5:$A$34,0))&"","") | C21: =FALSE() -> FALSE | D21: =FALSE() -> FALSE | E21: =D61/10 -> 0 | F21: =FALSE() -> FALSE | G21: =F61/10 -> 0 | H21: =FALSE() -> FALSE | I21: =H61/10 -> 0 | J21: =FALSE() -> FALSE | K21: =J61/10 -> 0 | L21: =FALSE() -> FALSE | M21: =L61/10 -> 0 | N21: =FALSE() -> FALSE | O21: =N61/10 -> 0 | P21: =FALSE() -> FALSE | Q21: =P61/10 -> 0
A22: P011 | B22: =IFERROR(INDEX(成員名單!$B$5:$B$34,MATCH($A22,成員名單!$A$5:$A$34,0))&"","") | C22: =FALSE() -> FALSE | D22: =FALSE() -> FALSE | E22: =D62/10 -> 0 | F22: =FALSE() -> FALSE | G22: =F62/10 -> 0 | H22: =FALSE() -> FALSE | I22: =H62/10 -> 0 | J22: =FALSE() -> FALSE | K22: =J62/10 -> 0 | L22: =FALSE() -> FALSE | M22: =L62/10 -> 0 | N22: =FALSE() -> FALSE | O22: =N62/10 -> 0 | P22: =FALSE() -> FALSE | Q22: =P62/10 -> 0
A23: P012 | B23: =IFERROR(INDEX(成員名單!$B$5:$B$34,MATCH($A23,成員名單!$A$5:$A$34,0))&"","") | C23: =FALSE() -> FALSE | D23: =FALSE() -> FALSE | E23: =D63/10 -> 0 | F23: =FALSE() -> FALSE | G23: =F63/10 -> 0 | H23: =FALSE() -> FALSE | I23: =H63/10 -> 0 | J23: =FALSE() -> FALSE | K23: =J63/10 -> 0 | L23: =FALSE() -> FALSE | M23: =L63/10 -> 0 | N23: =FALSE() -> FALSE | O23: =N63/10 -> 0 | P23: =FALSE() -> FALSE | Q23: =P63/10 -> 0
... A41: P030 | B41: =IFERROR(INDEX(成員名單!$B$5:$B$34,MATCH($A41,成員名單!$A$5:$A$34,0))&"","") | C41: =FALSE() -> FALSE | D41: =FALSE() -> FALSE | E41: =D81/10 -> 0 | F41: =FALSE() -> FALSE | G41: =F81/10 -> 0 | H41: =FALSE() -> FALSE | I41: =H81/10 -> 0 | J41: =FALSE() -> FALSE | K41: =J81/10 -> 0 | L41: =FALSE() -> FALSE | M41: =L81/10 -> 0 | N41: =FALSE() -> FALSE | O41: =N81/10 -> 0 | P41: =FALSE() -> FALSE | Q41: =P81/10 -> 0
B42: 已分攤合計（元） | E42: =D51/10 -> 0 | G42: =F51/10 -> 0 | I42: =H51/10 -> 0 | K42: =J51/10 -> 0 | M42: =L51/10 -> 0 | O42: =N51/10 -> 0 | Q42: =P51/10 -> 0
D46: =IFERROR(IF(D$47,ROUND(D$6*10,0),0),0) -> 0 | F46: =IFERROR(IF(F$47,ROUND(F$6*10,0),0),0) -> 0 | H46: =IFERROR(IF(H$47,ROUND(H$6*10,0),0),0) -> 0 | J46: =IFERROR(IF(J$47,ROUND(J$6*10,0),0),0) -> 0 | L46: =IFERROR(IF(L$47,ROUND(L$6*10,0),0),0) -> 0 | N46: =IFERROR(IF(N$47,ROUND(N$6*10,0),0),0) -> 0 | P46: =IFERROR(IF(P$47,ROUND(P$6*10,0),0),0) -> 0
D47: =IF(LEN(TRIM(D$6&""))=0,TRUE(),IFERROR(AND(ISNUMBER(D$6),D$6>=0,D$6<=100000000,ROUND(D$6,1)=D$6),FALSE())) -> 1 | F47: =IF(LEN(TRIM(F$6&""))=0,TRUE(),IFERROR(AND(ISNUMBER(F$6),F$6>=0,F$6<=100000000,ROUND(F$6,1)=F$6),FALSE())) -> 1 | H47: =IF(LEN(TRIM(H$6&""))=0,TRUE(),IFERROR(AND(ISNUMBER(H$6),H$6>=0,H$6<=100000000,ROUND(H$6,1)=H$6),FALSE())) -> 1 | J47: =IF(LEN(TRIM(J$6&""))=0,TRUE(),IFERROR(AND(ISNUMBER(J$6),J$6>=0,J$6<=100000000,ROUND(J$6,1)=J$6),FALSE())) -> 1 | L47: =IF(LEN(TRIM(L$6&""))=0,TRUE(),IFERROR(AND(ISNUMBER(L$6),L$6>=0,L$6<=100000000,ROUND(L$6,1)=L$6),FALSE())) -> 1 | N47: =IF(LEN(TRIM(N$6&""))=0,TRUE(),IFERROR(AND(ISNUMBER(N$6),N$6>=0,N$6<=100000000,ROUND(N$6,1)=N$6),FALSE())) -> 1 | P47: =IF(LEN(TRIM(P$6&""))=0,TRUE(),IFERROR(AND(ISNUMBER(P$6),P$6>=0,P$6<=100000000,ROUND(P$6,1)=P$6),FALSE())) -> 1
D48: =IF(D$50,IF(AND($C$3=TRUE(),$C$49>0),SUMPRODUCT(--(LEN(TRIM($B$12:$B$41))>0),--(D$12:D$41=TRUE()),--($C$12:$C$41<>TRUE())),0),SUMPRODUCT(--(LEN(TRIM($B$12:$B$41))>0),--(D$12:D$41=TRUE()))) -> 0 | F48: =IF(F$50,IF(AND($C$3=TRUE(),$C$49>0),SUMPRODUCT(--(LEN(TRIM($B$12:$B$41))>0),--(F$12:F$41=TRUE()),--($C$12:$C$41<>TRUE())),0),SUMPRODUCT(--(LEN(TRIM($B$12:$B$41))>0),--(F$12:F$41=TRUE()))) -> 0 | H48: =IF(H$50,IF(AND($C$3=TRUE(),$C$49>0),SUMPRODUCT(--(LEN(TRIM($B$12:$B$41))>0),--(H$12:H$41=TRUE()),--($C$12:$C$41<>TRUE())),0),SUMPRODUCT(--(LEN(TRIM($B$12:$B$41))>0),--(H$12:H$41=TRUE()))) -> 0 | J48: =IF(J$50,IF(AND($C$3=TRUE(),$C$49>0),SUMPRODUCT(--(LEN(TRIM($B$12:$B$41))>0),--(J$12:J$41=TRUE()),--($C$12:$C$41<>TRUE())),0),SUMPRODUCT(--(LEN(TRIM($B$12:$B$41))>0),--(J$12:J$41=TRUE()))) -> 0 | L48: =IF(L$50,IF(AND($C$3=TRUE(),$C$49>0),SUMPRODUCT(--(LEN(TRIM($B$12:$B$41))>0),--(L$12:L$41=TRUE()),--($C$12:$C$41<>TRUE())),0),SUMPRODUCT(--(LEN(TRIM($B$12:$B$41))>0),--(L$12:L$41=TRUE()))) -> 0 | N48: =IF(N$50,IF(AND($C$3=TRUE(),$C$49>0),SUMPRODUCT(--(LEN(TRIM($B$12:$B$41))>0),--(N$12:N$41=TRUE()),--($C$12:$C$41<>TRUE())),0),SUMPRODUCT(--(LEN(TRIM($B$12:$B$41))>0),--(N$12:N$41=TRUE()))) -> 0 | P48: =IF(P$50,IF(AND($C$3=TRUE(),$C$49>0),SUMPRODUCT(--(LEN(TRIM($B$12:$B$41))>0),--(P$12:P$41=TRUE()),--($C$12:$C$41<>TRUE())),0),SUMPRODUCT(--(LEN(TRIM($B$12:$B$41))>0),--(P$12:P$41=TRUE()))) -> 0
C49: =SUMPRODUCT(--(LEN(TRIM($B$12:$B$41))>0),--($C$12:$C$41=TRUE())) -> 0
D50: =OR(D$5="油錢",D$5="租車費") -> 0 | F50: =OR(F$5="油錢",F$5="租車費") -> 0 | H50: =OR(H$5="油錢",H$5="租車費") -> 0 | J50: =OR(J$5="油錢",J$5="租車費") -> 1 | L50: =OR(L$5="油錢",L$5="租車費") -> 1 | N50: =OR(N$5="油錢",N$5="租車費") -> 0 | P50: =OR(P$5="油錢",P$5="租車費") -> 0
D51: =SUM(D52:D81) -> 0 | F51: =SUM(F52:F81) -> 0 | H51: =SUM(H52:H81) -> 0 | J51: =SUM(J52:J81) -> 0 | L51: =SUM(L52:L81) -> 0 | N51: =SUM(N52:N81) -> 0 | P51: =SUM(P52:P81) -> 0
A52: P001 | D52: =IF(AND(D$47,D$48>0,LEN(TRIM($B12))>0,D12=TRUE(),IF(D$50,$C12<>TRUE(),TRUE())),QUOTIENT(D$46,MAX(1,D$48))+IF(IF(D$50,SUMPRODUCT(--(LEN(TRIM($B$12:$B12))>0),--(D$12:D12=TRUE()),--($C$12:$C12<>TRUE())),SUMPRODUCT(--(LEN(TRIM($B$12:$B12))>0),--(D$12:D12=TRUE())))<=MOD(D$46,MAX(1,D$48)),1,0),0) -> 0 | F52: =IF(AND(F$47,F$48>0,LEN(TRIM($B12))>0,F12=TRUE(),IF(F$50,$C12<>TRUE(),TRUE())),QUOTIENT(F$46,MAX(1,F$48))+IF(IF(F$50,SUMPRODUCT(--(LEN(TRIM($B$12:$B12))>0),--(F$12:F12=TRUE()),--($C$12:$C12<>TRUE())),SUMPRODUCT(--(LEN(TRIM($B$12:$B12))>0),--(F$12:F12=TRUE())))<=MOD(F$46,MAX(1,F$48)),1,0),0) -> 0 | H52: =IF(AND(H$47,H$48>0,LEN(TRIM($B12))>0,H12=TRUE(),IF(H$50,$C12<>TRUE(),TRUE())),QUOTIENT(H$46,MAX(1,H$48))+IF(IF(H$50,SUMPRODUCT(--(LEN(TRIM($B$12:$B12))>0),--(H$12:H12=TRUE()),--($C$12:$C12<>TRUE())),SUMPRODUCT(--(LEN(TRIM($B$12:$B12))>0),--(H$12:H12=TRUE())))<=MOD(H$46,MAX(1,H$48)),1,0),0) -> 0 | J52: =IF(AND(J$47,J$48>0,LEN(TRIM($B12))>0,J12=TRUE(),IF(J$50,$C12<>TRUE(),TRUE())),QUOTIENT(J$46,MAX(1,J$48))+IF(IF(J$50,SUMPRODUCT(--(LEN(TRIM($B$12:$B12))>0),--(J$12:J12=TRUE()),--($C$12:$C12<>TRUE())),SUMPRODUCT(--(LEN(TRIM($B$12:$B12))>0),--(J$12:J12=TRUE())))<=MOD(J$46,MAX(1,J$48)),1,0),0) -> 0 | L52: =IF(AND(L$47,L$48>0,LEN(TRIM($B12))>0,L12=TRUE(),IF(L$50,$C12<>TRUE(),TRUE())),QUOTIENT(L$46,MAX(1,L$48))+IF(IF(L$50,SUMPRODUCT(--(LEN(TRIM($B$12:$B12))>0),--(L$12:L12=TRUE()),--($C$12:$C12<>TRUE())),SUMPRODUCT(--(LEN(TRIM($B$12:$B12))>0),--(L$12:L12=TRUE())))<=MOD(L$46,MAX(1,L$48)),1,0),0) -> 0 | N52: =IF(AND(N$47,N$48>0,LEN(TRIM($B12))>0,N12=TRUE(),IF(N$50,$C12<>TRUE(),TRUE())),QUOTIENT(N$46,MAX(1,N$48))+IF(IF(N$50,SUMPRODUCT(--(LEN(TRIM($B$12:$B12))>0),--(N$12:N12=TRUE()),--($C$12:$C12<>TRUE())),SUMPRODUCT(--(LEN(TRIM($B$12:$B12))>0),--(N$12:N12=TRUE())))<=MOD(N$46,MAX(1,N$48)),1,0),0) -> 0 | P52: =IF(AND(P$47,P$48>0,LEN(TRIM($B12))>0,P12=TRUE(),IF(P$50,$C12<>TRUE(),TRUE())),QUOTIENT(P$46,MAX(1,P$48))+IF(IF(P$50,SUMPRODUCT(--(LEN(TRIM($B$12:$B12))>0),--(P$12:P12=TRUE()),--($C$12:$C12<>TRUE())),SUMPRODUCT(--(LEN(TRIM($B$12:$B12))>0),--(P$12:P12=TRUE())))<=MOD(P$46,MAX(1,P$48)),1,0),0) -> 0
A53: P002 | D53: =IF(AND(D$47,D$48>0,LEN(TRIM($B13))>0,D13=TRUE(),IF(D$50,$C13<>TRUE(),TRUE())),QUOTIENT(D$46,MAX(1,D$48))+IF(IF(D$50,SUMPRODUCT(--(LEN(TRIM($B$12:$B13))>0),--(D$12:D13=TRUE()),--($C$12:$C13<>TRUE())),SUMPRODUCT(--(LEN(TRIM($B$12:$B13))>0),--(D$12:D13=TRUE())))<=MOD(D$46,MAX(1,D$48)),1,0),0) -> 0 | F53: =IF(AND(F$47,F$48>0,LEN(TRIM($B13))>0,F13=TRUE(),IF(F$50,$C13<>TRUE(),TRUE())),QUOTIENT(F$46,MAX(1,F$48))+IF(IF(F$50,SUMPRODUCT(--(LEN(TRIM($B$12:$B13))>0),--(F$12:F13=TRUE()),--($C$12:$C13<>TRUE())),SUMPRODUCT(--(LEN(TRIM($B$12:$B13))>0),--(F$12:F13=TRUE())))<=MOD(F$46,MAX(1,F$48)),1,0),0) -> 0 | H53: =IF(AND(H$47,H$48>0,LEN(TRIM($B13))>0,H13=TRUE(),IF(H$50,$C13<>TRUE(),TRUE())),QUOTIENT(H$46,MAX(1,H$48))+IF(IF(H$50,SUMPRODUCT(--(LEN(TRIM($B$12:$B13))>0),--(H$12:H13=TRUE()),--($C$12:$C13<>TRUE())),SUMPRODUCT(--(LEN(TRIM($B$12:$B13))>0),--(H$12:H13=TRUE())))<=MOD(H$46,MAX(1,H$48)),1,0),0) -> 0 | J53: =IF(AND(J$47,J$48>0,LEN(TRIM($B13))>0,J13=TRUE(),IF(J$50,$C13<>TRUE(),TRUE())),QUOTIENT(J$46,MAX(1,J$48))+IF(IF(J$50,SUMPRODUCT(--(LEN(TRIM($B$12:$B13))>0),--(J$12:J13=TRUE()),--($C$12:$C13<>TRUE())),SUMPRODUCT(--(LEN(TRIM($B$12:$B13))>0),--(J$12:J13=TRUE())))<=MOD(J$46,MAX(1,J$48)),1,0),0) -> 0 | L53: =IF(AND(L$47,L$48>0,LEN(TRIM($B13))>0,L13=TRUE(),IF(L$50,$C13<>TRUE(),TRUE())),QUOTIENT(L$46,MAX(1,L$48))+IF(IF(L$50,SUMPRODUCT(--(LEN(TRIM($B$12:$B13))>0),--(L$12:L13=TRUE()),--($C$12:$C13<>TRUE())),SUMPRODUCT(--(LEN(TRIM($B$12:$B13))>0),--(L$12:L13=TRUE())))<=MOD(L$46,MAX(1,L$48)),1,0),0) -> 0 | N53: =IF(AND(N$47,N$48>0,LEN(TRIM($B13))>0,N13=TRUE(),IF(N$50,$C13<>TRUE(),TRUE())),QUOTIENT(N$46,MAX(1,N$48))+IF(IF(N$50,SUMPRODUCT(--(LEN(TRIM($B$12:$B13))>0),--(N$12:N13=TRUE()),--($C$12:$C13<>TRUE())),SUMPRODUCT(--(LEN(TRIM($B$12:$B13))>0),--(N$12:N13=TRUE())))<=MOD(N$46,MAX(1,N$48)),1,0),0) -> 0 | P53: =IF(AND(P$47,P$48>0,LEN(TRIM($B13))>0,P13=TRUE(),IF(P$50,$C13<>TRUE(),TRUE())),QUOTIENT(P$46,MAX(1,P$48))+IF(IF(P$50,SUMPRODUCT(--(LEN(TRIM($B$12:$B13))>0),--(P$12:P13=TRUE()),--($C$12:$C13<>TRUE())),SUMPRODUCT(--(LEN(TRIM($B$12:$B13))>0),--(P$12:P13=TRUE())))<=MOD(P$46,MAX(1,P$48)),1,0),0) -> 0
A54: P003 | D54: =IF(AND(D$47,D$48>0,LEN(TRIM($B14))>0,D14=TRUE(),IF(D$50,$C14<>TRUE(),TRUE())),QUOTIENT(D$46,MAX(1,D$48))+IF(IF(D$50,SUMPRODUCT(--(LEN(TRIM($B$12:$B14))>0),--(D$12:D14=TRUE()),--($C$12:$C14<>TRUE())),SUMPRODUCT(--(LEN(TRIM($B$12:$B14))>0),--(D$12:D14=TRUE())))<=MOD(D$46,MAX(1,D$48)),1,0),0) -> 0 | F54: =IF(AND(F$47,F$48>0,LEN(TRIM($B14))>0,F14=TRUE(),IF(F$50,$C14<>TRUE(),TRUE())),QUOTIENT(F$46,MAX(1,F$48))+IF(IF(F$50,SUMPRODUCT(--(LEN(TRIM($B$12:$B14))>0),--(F$12:F14=TRUE()),--($C$12:$C14<>TRUE())),SUMPRODUCT(--(LEN(TRIM($B$12:$B14))>0),--(F$12:F14=TRUE())))<=MOD(F$46,MAX(1,F$48)),1,0),0) -> 0 | H54: =IF(AND(H$47,H$48>0,LEN(TRIM($B14))>0,H14=TRUE(),IF(H$50,$C14<>TRUE(),TRUE())),QUOTIENT(H$46,MAX(1,H$48))+IF(IF(H$50,SUMPRODUCT(--(LEN(TRIM($B$12:$B14))>0),--(H$12:H14=TRUE()),--($C$12:$C14<>TRUE())),SUMPRODUCT(--(LEN(TRIM($B$12:$B14))>0),--(H$12:H14=TRUE())))<=MOD(H$46,MAX(1,H$48)),1,0),0) -> 0 | J54: =IF(AND(J$47,J$48>0,LEN(TRIM($B14))>0,J14=TRUE(),IF(J$50,$C14<>TRUE(),TRUE())),QUOTIENT(J$46,MAX(1,J$48))+IF(IF(J$50,SUMPRODUCT(--(LEN(TRIM($B$12:$B14))>0),--(J$12:J14=TRUE()),--($C$12:$C14<>TRUE())),SUMPRODUCT(--(LEN(TRIM($B$12:$B14))>0),--(J$12:J14=TRUE())))<=MOD(J$46,MAX(1,J$48)),1,0),0) -> 0 | L54: =IF(AND(L$47,L$48>0,LEN(TRIM($B14))>0,L14=TRUE(),IF(L$50,$C14<>TRUE(),TRUE())),QUOTIENT(L$46,MAX(1,L$48))+IF(IF(L$50,SUMPRODUCT(--(LEN(TRIM($B$12:$B14))>0),--(L$12:L14=TRUE()),--($C$12:$C14<>TRUE())),SUMPRODUCT(--(LEN(TRIM($B$12:$B14))>0),--(L$12:L14=TRUE())))<=MOD(L$46,MAX(1,L$48)),1,0),0) -> 0 | N54: =IF(AND(N$47,N$48>0,LEN(TRIM($B14))>0,N14=TRUE(),IF(N$50,$C14<>TRUE(),TRUE())),QUOTIENT(N$46,MAX(1,N$48))+IF(IF(N$50,SUMPRODUCT(--(LEN(TRIM($B$12:$B14))>0),--(N$12:N14=TRUE()),--($C$12:$C14<>TRUE())),SUMPRODUCT(--(LEN(TRIM($B$12:$B14))>0),--(N$12:N14=TRUE())))<=MOD(N$46,MAX(1,N$48)),1,0),0) -> 0 | P54: =IF(AND(P$47,P$48>0,LEN(TRIM($B14))>0,P14=TRUE(),IF(P$50,$C14<>TRUE(),TRUE())),QUOTIENT(P$46,MAX(1,P$48))+IF(IF(P$50,SUMPRODUCT(--(LEN(TRIM($B$12:$B14))>0),--(P$12:P14=TRUE()),--($C$12:$C14<>TRUE())),SUMPRODUCT(--(LEN(TRIM($B$12:$B14))>0),--(P$12:P14=TRUE())))<=MOD(P$46,MAX(1,P$48)),1,0),0) -> 0
A55: P004 | D55: =IF(AND(D$47,D$48>0,LEN(TRIM($B15))>0,D15=TRUE(),IF(D$50,$C15<>TRUE(),TRUE())),QUOTIENT(D$46,MAX(1,D$48))+IF(IF(D$50,SUMPRODUCT(--(LEN(TRIM($B$12:$B15))>0),--(D$12:D15=TRUE()),--($C$12:$C15<>TRUE())),SUMPRODUCT(--(LEN(TRIM($B$12:$B15))>0),--(D$12:D15=TRUE())))<=MOD(D$46,MAX(1,D$48)),1,0),0) -> 0 | F55: =IF(AND(F$47,F$48>0,LEN(TRIM($B15))>0,F15=TRUE(),IF(F$50,$C15<>TRUE(),TRUE())),QUOTIENT(F$46,MAX(1,F$48))+IF(IF(F$50,SUMPRODUCT(--(LEN(TRIM($B$12:$B15))>0),--(F$12:F15=TRUE()),--($C$12:$C15<>TRUE())),SUMPRODUCT(--(LEN(TRIM($B$12:$B15))>0),--(F$12:F15=TRUE())))<=MOD(F$46,MAX(1,F$48)),1,0),0) -> 0 | H55: =IF(AND(H$47,H$48>0,LEN(TRIM($B15))>0,H15=TRUE(),IF(H$50,$C15<>TRUE(),TRUE())),QUOTIENT(H$46,MAX(1,H$48))+IF(IF(H$50,SUMPRODUCT(--(LEN(TRIM($B$12:$B15))>0),--(H$12:H15=TRUE()),--($C$12:$C15<>TRUE())),SUMPRODUCT(--(LEN(TRIM($B$12:$B15))>0),--(H$12:H15=TRUE())))<=MOD(H$46,MAX(1,H$48)),1,0),0) -> 0 | J55: =IF(AND(J$47,J$48>0,LEN(TRIM($B15))>0,J15=TRUE(),IF(J$50,$C15<>TRUE(),TRUE())),QUOTIENT(J$46,MAX(1,J$48))+IF(IF(J$50,SUMPRODUCT(--(LEN(TRIM($B$12:$B15))>0),--(J$12:J15=TRUE()),--($C$12:$C15<>TRUE())),SUMPRODUCT(--(LEN(TRIM($B$12:$B15))>0),--(J$12:J15=TRUE())))<=MOD(J$46,MAX(1,J$48)),1,0),0) -> 0 | L55: =IF(AND(L$47,L$48>0,LEN(TRIM($B15))>0,L15=TRUE(),IF(L$50,$C15<>TRUE(),TRUE())),QUOTIENT(L$46,MAX(1,L$48))+IF(IF(L$50,SUMPRODUCT(--(LEN(TRIM($B$12:$B15))>0),--(L$12:L15=TRUE()),--($C$12:$C15<>TRUE())),SUMPRODUCT(--(LEN(TRIM($B$12:$B15))>0),--(L$12:L15=TRUE())))<=MOD(L$46,MAX(1,L$48)),1,0),0) -> 0 | N55: =IF(AND(N$47,N$48>0,LEN(TRIM($B15))>0,N15=TRUE(),IF(N$50,$C15<>TRUE(),TRUE())),QUOTIENT(N$46,MAX(1,N$48))+IF(IF(N$50,SUMPRODUCT(--(LEN(TRIM($B$12:$B15))>0),--(N$12:N15=TRUE()),--($C$12:$C15<>TRUE())),SUMPRODUCT(--(LEN(TRIM($B$12:$B15))>0),--(N$12:N15=TRUE())))<=MOD(N$46,MAX(1,N$48)),1,0),0) -> 0 | P55: =IF(AND(P$47,P$48>0,LEN(TRIM($B15))>0,P15=TRUE(),IF(P$50,$C15<>TRUE(),TRUE())),QUOTIENT(P$46,MAX(1,P$48))+IF(IF(P$50,SUMPRODUCT(--(LEN(TRIM($B$12:$B15))>0),--(P$12:P15=TRUE()),--($C$12:$C15<>TRUE())),SUMPRODUCT(--(LEN(TRIM($B$12:$B15))>0),--(P$12:P15=TRUE())))<=MOD(P$46,MAX(1,P$48)),1,0),0) -> 0
A56: P005 | D56: =IF(AND(D$47,D$48>0,LEN(TRIM($B16))>0,D16=TRUE(),IF(D$50,$C16<>TRUE(),TRUE())),QUOTIENT(D$46,MAX(1,D$48))+IF(IF(D$50,SUMPRODUCT(--(LEN(TRIM($B$12:$B16))>0),--(D$12:D16=TRUE()),--($C$12:$C16<>TRUE())),SUMPRODUCT(--(LEN(TRIM($B$12:$B16))>0),--(D$12:D16=TRUE())))<=MOD(D$46,MAX(1,D$48)),1,0),0) -> 0 | F56: =IF(AND(F$47,F$48>0,LEN(TRIM($B16))>0,F16=TRUE(),IF(F$50,$C16<>TRUE(),TRUE())),QUOTIENT(F$46,MAX(1,F$48))+IF(IF(F$50,SUMPRODUCT(--(LEN(TRIM($B$12:$B16))>0),--(F$12:F16=TRUE()),--($C$12:$C16<>TRUE())),SUMPRODUCT(--(LEN(TRIM($B$12:$B16))>0),--(F$12:F16=TRUE())))<=MOD(F$46,MAX(1,F$48)),1,0),0) -> 0 | H56: =IF(AND(H$47,H$48>0,LEN(TRIM($B16))>0,H16=TRUE(),IF(H$50,$C16<>TRUE(),TRUE())),QUOTIENT(H$46,MAX(1,H$48))+IF(IF(H$50,SUMPRODUCT(--(LEN(TRIM($B$12:$B16))>0),--(H$12:H16=TRUE()),--($C$12:$C16<>TRUE())),SUMPRODUCT(--(LEN(TRIM($B$12:$B16))>0),--(H$12:H16=TRUE())))<=MOD(H$46,MAX(1,H$48)),1,0),0) -> 0 | J56: =IF(AND(J$47,J$48>0,LEN(TRIM($B16))>0,J16=TRUE(),IF(J$50,$C16<>TRUE(),TRUE())),QUOTIENT(J$46,MAX(1,J$48))+IF(IF(J$50,SUMPRODUCT(--(LEN(TRIM($B$12:$B16))>0),--(J$12:J16=TRUE()),--($C$12:$C16<>TRUE())),SUMPRODUCT(--(LEN(TRIM($B$12:$B16))>0),--(J$12:J16=TRUE())))<=MOD(J$46,MAX(1,J$48)),1,0),0) -> 0 | L56: =IF(AND(L$47,L$48>0,LEN(TRIM($B16))>0,L16=TRUE(),IF(L$50,$C16<>TRUE(),TRUE())),QUOTIENT(L$46,MAX(1,L$48))+IF(IF(L$50,SUMPRODUCT(--(LEN(TRIM($B$12:$B16))>0),--(L$12:L16=TRUE()),--($C$12:$C16<>TRUE())),SUMPRODUCT(--(LEN(TRIM($B$12:$B16))>0),--(L$12:L16=TRUE())))<=MOD(L$46,MAX(1,L$48)),1,0),0) -> 0 | N56: =IF(AND(N$47,N$48>0,LEN(TRIM($B16))>0,N16=TRUE(),IF(N$50,$C16<>TRUE(),TRUE())),QUOTIENT(N$46,MAX(1,N$48))+IF(IF(N$50,SUMPRODUCT(--(LEN(TRIM($B$12:$B16))>0),--(N$12:N16=TRUE()),--($C$12:$C16<>TRUE())),SUMPRODUCT(--(LEN(TRIM($B$12:$B16))>0),--(N$12:N16=TRUE())))<=MOD(N$46,MAX(1,N$48)),1,0),0) -> 0 | P56: =IF(AND(P$47,P$48>0,LEN(TRIM($B16))>0,P16=TRUE(),IF(P$50,$C16<>TRUE(),TRUE())),QUOTIENT(P$46,MAX(1,P$48))+IF(IF(P$50,SUMPRODUCT(--(LEN(TRIM($B$12:$B16))>0),--(P$12:P16=TRUE()),--($C$12:$C16<>TRUE())),SUMPRODUCT(--(LEN(TRIM($B$12:$B16))>0),--(P$12:P16=TRUE())))<=MOD(P$46,MAX(1,P$48)),1,0),0) -> 0
A57: P006 | D57: =IF(AND(D$47,D$48>0,LEN(TRIM($B17))>0,D17=TRUE(),IF(D$50,$C17<>TRUE(),TRUE())),QUOTIENT(D$46,MAX(1,D$48))+IF(IF(D$50,SUMPRODUCT(--(LEN(TRIM($B$12:$B17))>0),--(D$12:D17=TRUE()),--($C$12:$C17<>TRUE())),SUMPRODUCT(--(LEN(TRIM($B$12:$B17))>0),--(D$12:D17=TRUE())))<=MOD(D$46,MAX(1,D$48)),1,0),0) -> 0 | F57: =IF(AND(F$47,F$48>0,LEN(TRIM($B17))>0,F17=TRUE(),IF(F$50,$C17<>TRUE(),TRUE())),QUOTIENT(F$46,MAX(1,F$48))+IF(IF(F$50,SUMPRODUCT(--(LEN(TRIM($B$12:$B17))>0),--(F$12:F17=TRUE()),--($C$12:$C17<>TRUE())),SUMPRODUCT(--(LEN(TRIM($B$12:$B17))>0),--(F$12:F17=TRUE())))<=MOD(F$46,MAX(1,F$48)),1,0),0) -> 0 | H57: =IF(AND(H$47,H$48>0,LEN(TRIM($B17))>0,H17=TRUE(),IF(H$50,$C17<>TRUE(),TRUE())),QUOTIENT(H$46,MAX(1,H$48))+IF(IF(H$50,SUMPRODUCT(--(LEN(TRIM($B$12:$B17))>0),--(H$12:H17=TRUE()),--($C$12:$C17<>TRUE())),SUMPRODUCT(--(LEN(TRIM($B$12:$B17))>0),--(H$12:H17=TRUE())))<=MOD(H$46,MAX(1,H$48)),1,0),0) -> 0 | J57: =IF(AND(J$47,J$48>0,LEN(TRIM($B17))>0,J17=TRUE(),IF(J$50,$C17<>TRUE(),TRUE())),QUOTIENT(J$46,MAX(1,J$48))+IF(IF(J$50,SUMPRODUCT(--(LEN(TRIM($B$12:$B17))>0),--(J$12:J17=TRUE()),--($C$12:$C17<>TRUE())),SUMPRODUCT(--(LEN(TRIM($B$12:$B17))>0),--(J$12:J17=TRUE())))<=MOD(J$46,MAX(1,J$48)),1,0),0) -> 0 | L57: =IF(AND(L$47,L$48>0,LEN(TRIM($B17))>0,L17=TRUE(),IF(L$50,$C17<>TRUE(),TRUE())),QUOTIENT(L$46,MAX(1,L$48))+IF(IF(L$50,SUMPRODUCT(--(LEN(TRIM($B$12:$B17))>0),--(L$12:L17=TRUE()),--($C$12:$C17<>TRUE())),SUMPRODUCT(--(LEN(TRIM($B$12:$B17))>0),--(L$12:L17=TRUE())))<=MOD(L$46,MAX(1,L$48)),1,0),0) -> 0 | N57: =IF(AND(N$47,N$48>0,LEN(TRIM($B17))>0,N17=TRUE(),IF(N$50,$C17<>TRUE(),TRUE())),QUOTIENT(N$46,MAX(1,N$48))+IF(IF(N$50,SUMPRODUCT(--(LEN(TRIM($B$12:$B17))>0),--(N$12:N17=TRUE()),--($C$12:$C17<>TRUE())),SUMPRODUCT(--(LEN(TRIM($B$12:$B17))>0),--(N$12:N17=TRUE())))<=MOD(N$46,MAX(1,N$48)),1,0),0) -> 0 | P57: =IF(AND(P$47,P$48>0,LEN(TRIM($B17))>0,P17=TRUE(),IF(P$50,$C17<>TRUE(),TRUE())),QUOTIENT(P$46,MAX(1,P$48))+IF(IF(P$50,SUMPRODUCT(--(LEN(TRIM($B$12:$B17))>0),--(P$12:P17=TRUE()),--($C$12:$C17<>TRUE())),SUMPRODUCT(--(LEN(TRIM($B$12:$B17))>0),--(P$12:P17=TRUE())))<=MOD(P$46,MAX(1,P$48)),1,0),0) -> 0
A58: P007 | D58: =IF(AND(D$47,D$48>0,LEN(TRIM($B18))>0,D18=TRUE(),IF(D$50,$C18<>TRUE(),TRUE())),QUOTIENT(D$46,MAX(1,D$48))+IF(IF(D$50,SUMPRODUCT(--(LEN(TRIM($B$12:$B18))>0),--(D$12:D18=TRUE()),--($C$12:$C18<>TRUE())),SUMPRODUCT(--(LEN(TRIM($B$12:$B18))>0),--(D$12:D18=TRUE())))<=MOD(D$46,MAX(1,D$48)),1,0),0) -> 0 | F58: =IF(AND(F$47,F$48>0,LEN(TRIM($B18))>0,F18=TRUE(),IF(F$50,$C18<>TRUE(),TRUE())),QUOTIENT(F$46,MAX(1,F$48))+IF(IF(F$50,SUMPRODUCT(--(LEN(TRIM($B$12:$B18))>0),--(F$12:F18=TRUE()),--($C$12:$C18<>TRUE())),SUMPRODUCT(--(LEN(TRIM($B$12:$B18))>0),--(F$12:F18=TRUE())))<=MOD(F$46,MAX(1,F$48)),1,0),0) -> 0 | H58: =IF(AND(H$47,H$48>0,LEN(TRIM($B18))>0,H18=TRUE(),IF(H$50,$C18<>TRUE(),TRUE())),QUOTIENT(H$46,MAX(1,H$48))+IF(IF(H$50,SUMPRODUCT(--(LEN(TRIM($B$12:$B18))>0),--(H$12:H18=TRUE()),--($C$12:$C18<>TRUE())),SUMPRODUCT(--(LEN(TRIM($B$12:$B18))>0),--(H$12:H18=TRUE())))<=MOD(H$46,MAX(1,H$48)),1,0),0) -> 0 | J58: =IF(AND(J$47,J$48>0,LEN(TRIM($B18))>0,J18=TRUE(),IF(J$50,$C18<>TRUE(),TRUE())),QUOTIENT(J$46,MAX(1,J$48))+IF(IF(J$50,SUMPRODUCT(--(LEN(TRIM($B$12:$B18))>0),--(J$12:J18=TRUE()),--($C$12:$C18<>TRUE())),SUMPRODUCT(--(LEN(TRIM($B$12:$B18))>0),--(J$12:J18=TRUE())))<=MOD(J$46,MAX(1,J$48)),1,0),0) -> 0 | L58: =IF(AND(L$47,L$48>0,LEN(TRIM($B18))>0,L18=TRUE(),IF(L$50,$C18<>TRUE(),TRUE())),QUOTIENT(L$46,MAX(1,L$48))+IF(IF(L$50,SUMPRODUCT(--(LEN(TRIM($B$12:$B18))>0),--(L$12:L18=TRUE()),--($C$12:$C18<>TRUE())),SUMPRODUCT(--(LEN(TRIM($B$12:$B18))>0),--(L$12:L18=TRUE())))<=MOD(L$46,MAX(1,L$48)),1,0),0) -> 0 | N58: =IF(AND(N$47,N$48>0,LEN(TRIM($B18))>0,N18=TRUE(),IF(N$50,$C18<>TRUE(),TRUE())),QUOTIENT(N$46,MAX(1,N$48))+IF(IF(N$50,SUMPRODUCT(--(LEN(TRIM($B$12:$B18))>0),--(N$12:N18=TRUE()),--($C$12:$C18<>TRUE())),SUMPRODUCT(--(LEN(TRIM($B$12:$B18))>0),--(N$12:N18=TRUE())))<=MOD(N$46,MAX(1,N$48)),1,0),0) -> 0 | P58: =IF(AND(P$47,P$48>0,LEN(TRIM($B18))>0,P18=TRUE(),IF(P$50,$C18<>TRUE(),TRUE())),QUOTIENT(P$46,MAX(1,P$48))+IF(IF(P$50,SUMPRODUCT(--(LEN(TRIM($B$12:$B18))>0),--(P$12:P18=TRUE()),--($C$12:$C18<>TRUE())),SUMPRODUCT(--(LEN(TRIM($B$12:$B18))>0),--(P$12:P18=TRUE())))<=MOD(P$46,MAX(1,P$48)),1,0),0) -> 0
A59: P008 | D59: =IF(AND(D$47,D$48>0,LEN(TRIM($B19))>0,D19=TRUE(),IF(D$50,$C19<>TRUE(),TRUE())),QUOTIENT(D$46,MAX(1,D$48))+IF(IF(D$50,SUMPRODUCT(--(LEN(TRIM($B$12:$B19))>0),--(D$12:D19=TRUE()),--($C$12:$C19<>TRUE())),SUMPRODUCT(--(LEN(TRIM($B$12:$B19))>0),--(D$12:D19=TRUE())))<=MOD(D$46,MAX(1,D$48)),1,0),0) -> 0 | F59: =IF(AND(F$47,F$48>0,LEN(TRIM($B19))>0,F19=TRUE(),IF(F$50,$C19<>TRUE(),TRUE())),QUOTIENT(F$46,MAX(1,F$48))+IF(IF(F$50,SUMPRODUCT(--(LEN(TRIM($B$12:$B19))>0),--(F$12:F19=TRUE()),--($C$12:$C19<>TRUE())),SUMPRODUCT(--(LEN(TRIM($B$12:$B19))>0),--(F$12:F19=TRUE())))<=MOD(F$46,MAX(1,F$48)),1,0),0) -> 0 | H59: =IF(AND(H$47,H$48>0,LEN(TRIM($B19))>0,H19=TRUE(),IF(H$50,$C19<>TRUE(),TRUE())),QUOTIENT(H$46,MAX(1,H$48))+IF(IF(H$50,SUMPRODUCT(--(LEN(TRIM($B$12:$B19))>0),--(H$12:H19=TRUE()),--($C$12:$C19<>TRUE())),SUMPRODUCT(--(LEN(TRIM($B$12:$B19))>0),--(H$12:H19=TRUE())))<=MOD(H$46,MAX(1,H$48)),1,0),0) -> 0 | J59: =IF(AND(J$47,J$48>0,LEN(TRIM($B19))>0,J19=TRUE(),IF(J$50,$C19<>TRUE(),TRUE())),QUOTIENT(J$46,MAX(1,J$48))+IF(IF(J$50,SUMPRODUCT(--(LEN(TRIM($B$12:$B19))>0),--(J$12:J19=TRUE()),--($C$12:$C19<>TRUE())),SUMPRODUCT(--(LEN(TRIM($B$12:$B19))>0),--(J$12:J19=TRUE())))<=MOD(J$46,MAX(1,J$48)),1,0),0) -> 0 | L59: =IF(AND(L$47,L$48>0,LEN(TRIM($B19))>0,L19=TRUE(),IF(L$50,$C19<>TRUE(),TRUE())),QUOTIENT(L$46,MAX(1,L$48))+IF(IF(L$50,SUMPRODUCT(--(LEN(TRIM($B$12:$B19))>0),--(L$12:L19=TRUE()),--($C$12:$C19<>TRUE())),SUMPRODUCT(--(LEN(TRIM($B$12:$B19))>0),--(L$12:L19=TRUE())))<=MOD(L$46,MAX(1,L$48)),1,0),0) -> 0 | N59: =IF(AND(N$47,N$48>0,LEN(TRIM($B19))>0,N19=TRUE(),IF(N$50,$C19<>TRUE(),TRUE())),QUOTIENT(N$46,MAX(1,N$48))+IF(IF(N$50,SUMPRODUCT(--(LEN(TRIM($B$12:$B19))>0),--(N$12:N19=TRUE()),--($C$12:$C19<>TRUE())),SUMPRODUCT(--(LEN(TRIM($B$12:$B19))>0),--(N$12:N19=TRUE())))<=MOD(N$46,MAX(1,N$48)),1,0),0) -> 0 | P59: =IF(AND(P$47,P$48>0,LEN(TRIM($B19))>0,P19=TRUE(),IF(P$50,$C19<>TRUE(),TRUE())),QUOTIENT(P$46,MAX(1,P$48))+IF(IF(P$50,SUMPRODUCT(--(LEN(TRIM($B$12:$B19))>0),--(P$12:P19=TRUE()),--($C$12:$C19<>TRUE())),SUMPRODUCT(--(LEN(TRIM($B$12:$B19))>0),--(P$12:P19=TRUE())))<=MOD(P$46,MAX(1,P$48)),1,0),0) -> 0
A60: P009 | D60: =IF(AND(D$47,D$48>0,LEN(TRIM($B20))>0,D20=TRUE(),IF(D$50,$C20<>TRUE(),TRUE())),QUOTIENT(D$46,MAX(1,D$48))+IF(IF(D$50,SUMPRODUCT(--(LEN(TRIM($B$12:$B20))>0),--(D$12:D20=TRUE()),--($C$12:$C20<>TRUE())),SUMPRODUCT(--(LEN(TRIM($B$12:$B20))>0),--(D$12:D20=TRUE())))<=MOD(D$46,MAX(1,D$48)),1,0),0) -> 0 | F60: =IF(AND(F$47,F$48>0,LEN(TRIM($B20))>0,F20=TRUE(),IF(F$50,$C20<>TRUE(),TRUE())),QUOTIENT(F$46,MAX(1,F$48))+IF(IF(F$50,SUMPRODUCT(--(LEN(TRIM($B$12:$B20))>0),--(F$12:F20=TRUE()),--($C$12:$C20<>TRUE())),SUMPRODUCT(--(LEN(TRIM($B$12:$B20))>0),--(F$12:F20=TRUE())))<=MOD(F$46,MAX(1,F$48)),1,0),0) -> 0 | H60: =IF(AND(H$47,H$48>0,LEN(TRIM($B20))>0,H20=TRUE(),IF(H$50,$C20<>TRUE(),TRUE())),QUOTIENT(H$46,MAX(1,H$48))+IF(IF(H$50,SUMPRODUCT(--(LEN(TRIM($B$12:$B20))>0),--(H$12:H20=TRUE()),--($C$12:$C20<>TRUE())),SUMPRODUCT(--(LEN(TRIM($B$12:$B20))>0),--(H$12:H20=TRUE())))<=MOD(H$46,MAX(1,H$48)),1,0),0) -> 0 | J60: =IF(AND(J$47,J$48>0,LEN(TRIM($B20))>0,J20=TRUE(),IF(J$50,$C20<>TRUE(),TRUE())),QUOTIENT(J$46,MAX(1,J$48))+IF(IF(J$50,SUMPRODUCT(--(LEN(TRIM($B$12:$B20))>0),--(J$12:J20=TRUE()),--($C$12:$C20<>TRUE())),SUMPRODUCT(--(LEN(TRIM($B$12:$B20))>0),--(J$12:J20=TRUE())))<=MOD(J$46,MAX(1,J$48)),1,0),0) -> 0 | L60: =IF(AND(L$47,L$48>0,LEN(TRIM($B20))>0,L20=TRUE(),IF(L$50,$C20<>TRUE(),TRUE())),QUOTIENT(L$46,MAX(1,L$48))+IF(IF(L$50,SUMPRODUCT(--(LEN(TRIM($B$12:$B20))>0),--(L$12:L20=TRUE()),--($C$12:$C20<>TRUE())),SUMPRODUCT(--(LEN(TRIM($B$12:$B20))>0),--(L$12:L20=TRUE())))<=MOD(L$46,MAX(1,L$48)),1,0),0) -> 0 | N60: =IF(AND(N$47,N$48>0,LEN(TRIM($B20))>0,N20=TRUE(),IF(N$50,$C20<>TRUE(),TRUE())),QUOTIENT(N$46,MAX(1,N$48))+IF(IF(N$50,SUMPRODUCT(--(LEN(TRIM($B$12:$B20))>0),--(N$12:N20=TRUE()),--($C$12:$C20<>TRUE())),SUMPRODUCT(--(LEN(TRIM($B$12:$B20))>0),--(N$12:N20=TRUE())))<=MOD(N$46,MAX(1,N$48)),1,0),0) -> 0 | P60: =IF(AND(P$47,P$48>0,LEN(TRIM($B20))>0,P20=TRUE(),IF(P$50,$C20<>TRUE(),TRUE())),QUOTIENT(P$46,MAX(1,P$48))+IF(IF(P$50,SUMPRODUCT(--(LEN(TRIM($B$12:$B20))>0),--(P$12:P20=TRUE()),--($C$12:$C20<>TRUE())),SUMPRODUCT(--(LEN(TRIM($B$12:$B20))>0),--(P$12:P20=TRUE())))<=MOD(P$46,MAX(1,P$48)),1,0),0) -> 0
...

Sheet 第 2 天
A1: d_mveoqnqvknl0u8rnq | D1: e_mveoqnqvprlb9qdxl | F1: e_mveoqnqvpcg1v17dy | H1: e_mveoqnqvn8ozy70xt | J1: e_mveoqnqvon1oyxr8g | L1: e_mveoqnqv9jnhdtg9p | N1: e_mveoqnqv5gloqjee8 | P1: e_mveoqnqvqwivafnoo
B2: 第 2 天 | D2: 全選／取消全選：選取費用欄後使用「旅伴帳本」選單。
B3: 當日用車 | C3: =FALSE() -> FALSE | D3: 司機只免當日油錢與租車費；餐費、停車費與其他正常分攤。
B4: 名稱 | D4: 早餐 | F4: 午餐 | H4: 晚餐 | J4: 油錢 | L4: 租車費 | N4: 停車費 | P4: 其他
B5: 類別 | D5: 早餐 | F5: 午餐 | H5: 晚餐 | J5: 油錢 | L5: 租車費 | N5: 停車費 | P5: 其他
B6: 總金額（元） | E6: 元 | G6: 元 | I6: 元 | K6: 元 | M6: 元 | O6: 元 | Q6: 元
B7: 代墊者 ID | E7: =IFERROR(INDEX(成員名單!$B$5:$B$34,MATCH(D7,成員名單!$A$5:$A$34,0))&"","") | G7: =IFERROR(INDEX(成員名單!$B$5:$B$34,MATCH(F7,成員名單!$A$5:$A$34,0))&"","") | I7: =IFERROR(INDEX(成員名單!$B$5:$B$34,MATCH(H7,成員名單!$A$5:$A$34,0))&"","") | K7: =IFERROR(INDEX(成員名單!$B$5:$B$34,MATCH(J7,成員名單!$A$5:$A$34,0))&"","") | M7: =IFERROR(INDEX(成員名單!$B$5:$B$34,MATCH(L7,成員名單!$A$5:$A$34,0))&"","") | O7: =IFERROR(INDEX(成員名單!$B$5:$B$34,MATCH(N7,成員名單!$A$5:$A$34,0))&"","") | Q7: =IFERROR(INDEX(成員名單!$B$5:$B$34,MATCH(P7,成員名單!$A$5:$A$34,0))&"","")
B8: 分攤人數 | D8: =IF(D$47,D$48,0) -> 0 | E8: 人 | F8: =IF(F$47,F$48,0) -> 0 | G8: 人 | H8: =IF(H$47,H$48,0) -> 0 | I8: 人 | J8: =IF(J$47,J$48,0) -> 0 | K8: 人 | L8: =IF(L$47,L$48,0) -> 0 | M8: 人 | N8: =IF(N$47,N$48,0) -> 0 | O8: 人 | P8: =IF(P$47,P$48,0) -> 0 | Q8: 人
B9: 每人金額範圍 | D9: =IF(OR(NOT(D$47),D$48=0),"暫不分攤",TEXT(QUOTIENT(D$46,MAX(1,D$48))/10,"0.0")&IF(MOD(D$46,MAX(1,D$48))>0,"–"&TEXT((QUOTIENT(D$46,MAX(1,D$48))+1)/10,"0.0"),"")&" 元／人") -> 暫不分攤 | F9: =IF(OR(NOT(F$47),F$48=0),"暫不分攤",TEXT(QUOTIENT(F$46,MAX(1,F$48))/10,"0.0")&IF(MOD(F$46,MAX(1,F$48))>0,"–"&TEXT((QUOTIENT(F$46,MAX(1,F$48))+1)/10,"0.0"),"")&" 元／人") -> 暫不分攤 | H9: =IF(OR(NOT(H$47),H$48=0),"暫不分攤",TEXT(QUOTIENT(H$46,MAX(1,H$48))/10,"0.0")&IF(MOD(H$46,MAX(1,H$48))>0,"–"&TEXT((QUOTIENT(H$46,MAX(1,H$48))+1)/10,"0.0"),"")&" 元／人") -> 暫不分攤 | J9: =IF(OR(NOT(J$47),J$48=0),"暫不分攤",TEXT(QUOTIENT(J$46,MAX(1,J$48))/10,"0.0")&IF(MOD(J$46,MAX(1,J$48))>0,"–"&TEXT((QUOTIENT(J$46,MAX(1,J$48))+1)/10,"0.0"),"")&" 元／人") -> 暫不分攤 | L9: =IF(OR(NOT(L$47),L$48=0),"暫不分攤",TEXT(QUOTIENT(L$46,MAX(1,L$48))/10,"0.0")&IF(MOD(L$46,MAX(1,L$48))>0,"–"&TEXT((QUOTIENT(L$46,MAX(1,L$48))+1)/10,"0.0"),"")&" 元／人") -> 暫不分攤 | N9: =IF(OR(NOT(N$47),N$48=0),"暫不分攤",TEXT(QUOTIENT(N$46,MAX(1,N$48))/10,"0.0")&IF(MOD(N$46,MAX(1,N$48))>0,"–"&TEXT((QUOTIENT(N$46,MAX(1,N$48))+1)/10,"0.0"),"")&" 元／人") -> 暫不分攤 | P9: =IF(OR(NOT(P$47),P$48=0),"暫不分攤",TEXT(QUOTIENT(P$46,MAX(1,P$48))/10,"0.0")&IF(MOD(P$46,MAX(1,P$48))>0,"–"&TEXT((QUOTIENT(P$46,MAX(1,P$48))+1)/10,"0.0"),"")&" 元／人") -> 暫不分攤
